ERROR 2018-10-23 16:00:14,542 exception 80 Invalid HTTP_HOST header: 'api.meiduo.site:8000'. You may need to add 'api.meiduo.site' to ALLOWED_HOSTS.
WARNING 2018-10-23 16:00:14,614 basehttp 124 "GET / HTTP/1.1" 400 61851
ERROR 2018-10-23 16:00:14,888 exception 80 Invalid HTTP_HOST header: 'api.meiduo.site:8000'. You may need to add 'api.meiduo.site' to ALLOWED_HOSTS.
WARNING 2018-10-23 16:00:14,922 basehttp 124 "GET /favicon.ico HTTP/1.1" 400 61935
INFO 2018-10-23 16:01:22,974 basehttp 124 "GET / HTTP/1.1" 200 1714
WARNING 2018-10-23 16:01:23,029 base 152 Not Found: /favicon.ico
WARNING 2018-10-23 16:01:23,030 basehttp 124 "GET /favicon.ico HTTP/1.1" 404 1968
WARNING 2018-10-24 16:21:17,308 base 152 Not Found: /usernames/jianhao/count/
WARNING 2018-10-24 16:21:17,309 basehttp 124 "GET /usernames/jianhao/count/ HTTP/1.1" 404 2007
WARNING 2018-10-24 16:52:18,772 base 152 Not Found: /mobiles/13590299759/count/
WARNING 2018-10-24 16:52:18,773 basehttp 124 "GET /mobiles/13590299759/count/ HTTP/1.1" 404 2013
WARNING 2018-10-24 16:52:18,863 base 152 Not Found: /mobiles/13590299759/count/
WARNING 2018-10-24 16:52:18,867 base 152 Not Found: /sms_code/13590299759/
WARNING 2018-10-24 16:52:18,867 basehttp 124 "GET /mobiles/13590299759/count/ HTTP/1.1" 404 2013
WARNING 2018-10-24 16:52:18,868 basehttp 124 "GET /sms_code/13590299759/ HTTP/1.1" 404 1998
WARNING 2018-10-24 16:53:42,531 base 152 Not Found: /mobiles/13590299759/count/
WARNING 2018-10-24 16:53:42,534 base 152 Not Found: /sms_code/13590299759/
WARNING 2018-10-24 16:53:42,534 basehttp 124 "GET /mobiles/13590299759/count/ HTTP/1.1" 404 2013
WARNING 2018-10-24 16:53:42,535 basehttp 124 "GET /sms_code/13590299759/ HTTP/1.1" 404 1998
WARNING 2018-10-24 16:54:54,420 base 152 Not Found: /mobiles/13590299759/count/
WARNING 2018-10-24 16:54:54,421 basehttp 124 "GET /mobiles/13590299759/count/ HTTP/1.1" 404 2013
WARNING 2018-10-24 16:54:54,425 base 152 Not Found: /sms_code/13590299759/
WARNING 2018-10-24 16:54:54,425 basehttp 124 "GET /sms_code/13590299759/ HTTP/1.1" 404 1998
WARNING 2018-10-24 16:55:16,166 base 152 Not Found: /mobiles/13590299759/count/
WARNING 2018-10-24 16:55:16,167 basehttp 124 "GET /mobiles/13590299759/count/ HTTP/1.1" 404 2013
WARNING 2018-10-24 16:55:31,706 base 152 Not Found: /mobiles/13590299759/count/
WARNING 2018-10-24 16:55:31,710 base 152 Not Found: /sms_code/13590299759/
WARNING 2018-10-24 16:55:31,710 basehttp 124 "GET /sms_code/13590299759/ HTTP/1.1" 404 1998
WARNING 2018-10-24 16:55:31,711 basehttp 124 "GET /mobiles/13590299759/count/ HTTP/1.1" 404 2013
WARNING 2018-10-24 16:59:57,241 base 152 Not Found: /mobiles/13590299759/count/
WARNING 2018-10-24 16:59:57,243 base 152 Not Found: /sms_code/13590299759/
WARNING 2018-10-24 16:59:57,244 basehttp 124 "GET /mobiles/13590299759/count/ HTTP/1.1" 404 2115
WARNING 2018-10-24 16:59:57,244 basehttp 124 "GET /sms_code/13590299759/ HTTP/1.1" 404 2100
WARNING 2018-10-24 17:03:19,943 base 152 Not Found: /mobiles/13590299759/count/
WARNING 2018-10-24 17:03:19,944 basehttp 124 "GET /mobiles/13590299759/count/ HTTP/1.1" 404 2202
ERROR 2018-10-24 17:03:19,951 exception 135 Internal Server Error: /sms_code/13590299759/
Traceback (most recent call last):
  File "/Users/huangjianhao/.virtualenvs/django_py3_1.11/lib/python3.6/site-packages/django/core/handlers/exception.py", line 41, in inner
    response = get_response(request)
  File "/Users/huangjianhao/.virtualenvs/django_py3_1.11/lib/python3.6/site-packages/django/core/handlers/base.py", line 187, in _get_response
    response = self.process_exception_by_middleware(e, request)
  File "/Users/huangjianhao/.virtualenvs/django_py3_1.11/lib/python3.6/site-packages/django/core/handlers/base.py", line 185, in _get_response
    response = wrapped_callback(request, *callback_args, **callback_kwargs)
  File "/Users/huangjianhao/.virtualenvs/django_py3_1.11/lib/python3.6/site-packages/django/views/decorators/csrf.py", line 58, in wrapped_view
    return view_func(*args, **kwargs)
  File "/Users/huangjianhao/.virtualenvs/django_py3_1.11/lib/python3.6/site-packages/django/views/generic/base.py", line 68, in view
    return self.dispatch(request, *args, **kwargs)
  File "/Users/huangjianhao/.virtualenvs/django_py3_1.11/lib/python3.6/site-packages/rest_framework/views.py", line 483, in dispatch
    response = self.handle_exception(exc)
  File "/Users/huangjianhao/.virtualenvs/django_py3_1.11/lib/python3.6/site-packages/rest_framework/views.py", line 443, in handle_exception
    self.raise_uncaught_exception(exc)
  File "/Users/huangjianhao/.virtualenvs/django_py3_1.11/lib/python3.6/site-packages/rest_framework/views.py", line 480, in dispatch
    response = handler(request, *args, **kwargs)
  File "/Users/huangjianhao/Downloads/PythonProject/meiduo_mall/meiduo/meiduo/apps/verifications/views.py", line 35, in get
    redis_pipeline.setex('sms_code_' + mobile, constants.SMS_CODE_EXPIRES)
TypeError: setex() missing 1 required positional argument: 'value'
ERROR 2018-10-24 17:03:19,999 basehttp 124 "GET /sms_code/13590299759/ HTTP/1.1" 500 16510
WARNING 2018-10-24 17:04:56,428 base 152 Not Found: /mobiles/13590299759/count/
WARNING 2018-10-24 17:04:56,430 basehttp 124 "GET /mobiles/13590299759/count/ HTTP/1.1" 404 2202
INFO 2018-10-24 17:04:56,477 basehttp 124 "GET /sms_code/13590299759/ HTTP/1.1" 200 16
WARNING 2018-10-24 17:06:52,129 base 152 Not Found: /mobiles/13590299759/count/
WARNING 2018-10-24 17:06:52,131 basehttp 124 "GET /mobiles/13590299759/count/ HTTP/1.1" 404 2202
INFO 2018-10-24 17:06:52,173 basehttp 124 "GET /sms_code/13590299759/ HTTP/1.1" 200 16
WARNING 2018-10-24 17:16:34,269 base 152 Not Found: /mobiles/13590299759/count/
WARNING 2018-10-24 17:16:34,278 basehttp 124 "GET /mobiles/13590299759/count/ HTTP/1.1" 404 2202
INFO 2018-10-24 17:16:34,398 basehttp 124 "GET /sms_code/13590299759/ HTTP/1.1" 200 16
WARNING 2018-10-24 17:19:33,487 base 152 Not Found: /mobiles/13590299759/count/
WARNING 2018-10-24 17:19:33,497 basehttp 124 "GET /mobiles/13590299759/count/ HTTP/1.1" 404 2202
INFO 2018-10-24 17:19:33,618 basehttp 124 "GET /sms_code/13590299759/ HTTP/1.1" 200 16
WARNING 2018-10-24 17:34:53,472 base 152 Not Found: /mobiles/13590299759/count/
WARNING 2018-10-24 17:34:53,474 basehttp 124 "GET /mobiles/13590299759/count/ HTTP/1.1" 404 2202
INFO 2018-10-24 17:34:53,517 basehttp 124 "GET /sms_code/13590299759/ HTTP/1.1" 200 16
WARNING 2018-10-24 17:34:54,406 tasks 30 发送验证码短信[失败][ mobile: 13590299759 ]
WARNING 2018-10-24 17:36:55,744 base 152 Not Found: /mobiles/13590299759/count/
WARNING 2018-10-24 17:36:55,746 basehttp 124 "GET /mobiles/13590299759/count/ HTTP/1.1" 404 2202
INFO 2018-10-24 17:36:55,787 basehttp 124 "GET /sms_code/13590299759/ HTTP/1.1" 200 16
WARNING 2018-10-24 17:36:55,875 tasks 30 发送验证码短信[失败][ mobile: 13590299759 ]
WARNING 2018-10-24 17:54:59,819 base 152 Not Found: /mobiles/13590299759/count/
WARNING 2018-10-24 17:54:59,820 basehttp 124 "GET /mobiles/13590299759/count/ HTTP/1.1" 404 2202
WARNING 2018-10-24 17:54:59,908 base 152 Not Found: /mobiles/13590299759/count/
WARNING 2018-10-24 17:54:59,909 basehttp 124 "GET /mobiles/13590299759/count/ HTTP/1.1" 404 2202
INFO 2018-10-24 17:54:59,950 basehttp 124 "GET /sms_code/13590299759/ HTTP/1.1" 200 16
INFO 2018-10-24 17:55:00,323 tasks 29 发送验证码短信[正常][ mobile: 13590299759 ]
INFO 2018-10-25 16:10:20,145 basehttp 124 "GET /usernames/jianhao/count/ HTTP/1.1" 200 32
INFO 2018-10-25 16:10:33,407 basehttp 124 "GET /usernames/jianhao/count/ HTTP/1.1" 200 32
INFO 2018-10-25 16:15:18,354 basehttp 124 "GET /mobiles/13590299759/count/ HTTP/1.1" 200 41
INFO 2018-10-25 16:54:23,405 basehttp 124 "GET /usernames/jianhao/count/ HTTP/1.1" 200 32
INFO 2018-10-25 16:54:37,538 basehttp 124 "GET /mobiles/13590299759/count/ HTTP/1.1" 200 41
INFO 2018-10-25 16:54:39,424 basehttp 124 "GET /mobiles/13590299759/count/ HTTP/1.1" 200 41
INFO 2018-10-25 16:54:39,476 basehttp 124 "GET /sms_code/13590299759/ HTTP/1.1" 200 16
INFO 2018-10-25 16:54:40,581 tasks 29 发送验证码短信[正常][ mobile: 13590299759 ]
INFO 2018-10-25 16:54:55,702 basehttp 124 "OPTIONS /users/ HTTP/1.1" 200 0
WARNING 2018-10-25 16:54:55,711 base 152 Not Found: /users/
WARNING 2018-10-25 16:54:55,713 basehttp 124 "POST /users/ HTTP/1.1" 404 2531
INFO 2018-10-25 16:54:55,718 basehttp 124 "GET /usernames/jianhao/count/ HTTP/1.1" 200 32
INFO 2018-10-25 16:54:55,719 basehttp 124 "GET /mobiles/13590299759/count/ HTTP/1.1" 200 41
WARNING 2018-10-25 16:55:05,305 base 152 Not Found: /users/
WARNING 2018-10-25 16:55:05,308 basehttp 124 "POST /users/ HTTP/1.1" 404 2531
INFO 2018-10-25 16:55:05,318 basehttp 124 "GET /mobiles/13590299759/count/ HTTP/1.1" 200 41
INFO 2018-10-25 16:55:05,318 basehttp 124 "GET /usernames/jianhao/count/ HTTP/1.1" 200 32
WARNING 2018-10-25 16:55:27,693 base 152 Not Found: /users/
WARNING 2018-10-25 16:55:27,697 basehttp 124 "POST /users/ HTTP/1.1" 404 2531
INFO 2018-10-25 16:55:27,703 basehttp 124 "GET /usernames/jianhao/count/ HTTP/1.1" 200 32
INFO 2018-10-25 16:55:27,708 basehttp 124 "GET /mobiles/13590299759/count/ HTTP/1.1" 200 41
INFO 2018-10-25 16:56:45,164 basehttp 124 "GET /usernames/jianhao/count/ HTTP/1.1" 200 32
INFO 2018-10-25 16:56:45,165 basehttp 124 "GET /mobiles/13590299759/count/ HTTP/1.1" 200 41
ERROR 2018-10-25 16:56:45,169 exception 135 Internal Server Error: /users/
Traceback (most recent call last):
  File "/Users/huangjianhao/.virtualenvs/django_py3_1.11/lib/python3.6/site-packages/django/core/handlers/exception.py", line 41, in inner
    response = get_response(request)
  File "/Users/huangjianhao/.virtualenvs/django_py3_1.11/lib/python3.6/site-packages/django/core/handlers/base.py", line 187, in _get_response
    response = self.process_exception_by_middleware(e, request)
  File "/Users/huangjianhao/.virtualenvs/django_py3_1.11/lib/python3.6/site-packages/django/core/handlers/base.py", line 185, in _get_response
    response = wrapped_callback(request, *callback_args, **callback_kwargs)
  File "/Users/huangjianhao/.virtualenvs/django_py3_1.11/lib/python3.6/site-packages/django/views/decorators/csrf.py", line 58, in wrapped_view
    return view_func(*args, **kwargs)
  File "/Users/huangjianhao/.virtualenvs/django_py3_1.11/lib/python3.6/site-packages/django/views/generic/base.py", line 68, in view
    return self.dispatch(request, *args, **kwargs)
  File "/Users/huangjianhao/.virtualenvs/django_py3_1.11/lib/python3.6/site-packages/rest_framework/views.py", line 483, in dispatch
    response = self.handle_exception(exc)
  File "/Users/huangjianhao/.virtualenvs/django_py3_1.11/lib/python3.6/site-packages/rest_framework/views.py", line 443, in handle_exception
    self.raise_uncaught_exception(exc)
  File "/Users/huangjianhao/.virtualenvs/django_py3_1.11/lib/python3.6/site-packages/rest_framework/views.py", line 480, in dispatch
    response = handler(request, *args, **kwargs)
  File "/Users/huangjianhao/.virtualenvs/django_py3_1.11/lib/python3.6/site-packages/rest_framework/generics.py", line 192, in post
    return self.create(request, *args, **kwargs)
  File "/Users/huangjianhao/.virtualenvs/django_py3_1.11/lib/python3.6/site-packages/rest_framework/mixins.py", line 20, in create
    serializer.is_valid(raise_exception=True)
  File "/Users/huangjianhao/.virtualenvs/django_py3_1.11/lib/python3.6/site-packages/rest_framework/serializers.py", line 236, in is_valid
    self._validated_data = self.run_validation(self.initial_data)
  File "/Users/huangjianhao/.virtualenvs/django_py3_1.11/lib/python3.6/site-packages/rest_framework/serializers.py", line 438, in run_validation
    assert value is not None, '.validate() should return the validated data'
AssertionError: .validate() should return the validated data
ERROR 2018-10-25 16:56:45,221 basehttp 124 "POST /users/ HTTP/1.1" 500 17033
INFO 2018-10-25 16:58:00,150 basehttp 124 "GET /mobiles/13590299759/count/ HTTP/1.1" 200 41
INFO 2018-10-25 16:58:00,152 basehttp 124 "GET /usernames/jianhao/count/ HTTP/1.1" 200 32
WARNING 2018-10-25 16:58:00,156 basehttp 124 "POST /users/ HTTP/1.1" 400 43
INFO 2018-10-25 16:58:06,357 basehttp 124 "GET /mobiles/13590299759/count/ HTTP/1.1" 200 41
INFO 2018-10-25 16:58:06,388 basehttp 124 "GET /sms_code/13590299759/ HTTP/1.1" 200 16
INFO 2018-10-25 16:58:07,041 tasks 29 发送验证码短信[正常][ mobile: 13590299759 ]
INFO 2018-10-25 16:58:17,058 basehttp 124 "GET /mobiles/13590299759/count/ HTTP/1.1" 200 41
INFO 2018-10-25 16:58:17,058 basehttp 124 "GET /usernames/jianhao/count/ HTTP/1.1" 200 32
INFO 2018-10-25 16:58:17,173 basehttp 124 "POST /users/ HTTP/1.1" 201 52
INFO 2018-10-25 18:08:54,462 basehttp 124 "OPTIONS /authorizations/ HTTP/1.1" 200 0
INFO 2018-10-25 18:08:54,526 basehttp 124 "POST /authorizations/ HTTP/1.1" 200 209
INFO 2018-10-25 18:30:01,190 basehttp 124 "OPTIONS /authorizations/ HTTP/1.1" 200 0
ERROR 2018-10-25 18:30:01,219 exception 135 Internal Server Error: /authorizations/
Traceback (most recent call last):
  File "/Users/huangjianhao/.virtualenvs/django_py3_1.11/lib/python3.6/site-packages/django/core/handlers/exception.py", line 41, in inner
    response = get_response(request)
  File "/Users/huangjianhao/.virtualenvs/django_py3_1.11/lib/python3.6/site-packages/django/core/handlers/base.py", line 187, in _get_response
    response = self.process_exception_by_middleware(e, request)
  File "/Users/huangjianhao/.virtualenvs/django_py3_1.11/lib/python3.6/site-packages/django/core/handlers/base.py", line 185, in _get_response
    response = wrapped_callback(request, *callback_args, **callback_kwargs)
  File "/Users/huangjianhao/.virtualenvs/django_py3_1.11/lib/python3.6/site-packages/django/views/decorators/csrf.py", line 58, in wrapped_view
    return view_func(*args, **kwargs)
  File "/Users/huangjianhao/.virtualenvs/django_py3_1.11/lib/python3.6/site-packages/django/views/generic/base.py", line 68, in view
    return self.dispatch(request, *args, **kwargs)
  File "/Users/huangjianhao/.virtualenvs/django_py3_1.11/lib/python3.6/site-packages/rest_framework/views.py", line 483, in dispatch
    response = self.handle_exception(exc)
  File "/Users/huangjianhao/.virtualenvs/django_py3_1.11/lib/python3.6/site-packages/rest_framework/views.py", line 443, in handle_exception
    self.raise_uncaught_exception(exc)
  File "/Users/huangjianhao/.virtualenvs/django_py3_1.11/lib/python3.6/site-packages/rest_framework/views.py", line 480, in dispatch
    response = handler(request, *args, **kwargs)
  File "/Users/huangjianhao/.virtualenvs/django_py3_1.11/lib/python3.6/site-packages/rest_framework_jwt/views.py", line 57, in post
    if serializer.is_valid():
  File "/Users/huangjianhao/.virtualenvs/django_py3_1.11/lib/python3.6/site-packages/rest_framework/serializers.py", line 236, in is_valid
    self._validated_data = self.run_validation(self.initial_data)
  File "/Users/huangjianhao/.virtualenvs/django_py3_1.11/lib/python3.6/site-packages/rest_framework/serializers.py", line 437, in run_validation
    value = self.validate(value)
  File "/Users/huangjianhao/.virtualenvs/django_py3_1.11/lib/python3.6/site-packages/rest_framework_jwt/serializers.py", line 50, in validate
    user = authenticate(**credentials)
  File "/Users/huangjianhao/.virtualenvs/django_py3_1.11/lib/python3.6/site-packages/django/contrib/auth/__init__.py", line 70, in authenticate
    user = _authenticate_with_backend(backend, backend_path, request, credentials)
  File "/Users/huangjianhao/.virtualenvs/django_py3_1.11/lib/python3.6/site-packages/django/contrib/auth/__init__.py", line 116, in _authenticate_with_backend
    return backend.authenticate(*args, **credentials)
  File "/Users/huangjianhao/Downloads/PythonProject/meiduo_mall/meiduo/meiduo/apps/users/utils.py", line 44, in authenticate
    if user is not None and user.check_password():
TypeError: check_password() missing 1 required positional argument: 'raw_password'
ERROR 2018-10-25 18:30:01,267 basehttp 124 "POST /authorizations/ HTTP/1.1" 500 18006
INFO 2018-10-25 18:30:26,989 basehttp 124 "POST /authorizations/ HTTP/1.1" 200 209
INFO 2018-10-26 14:25:57,469 basehttp 124 "OPTIONS /authorizations/ HTTP/1.1" 200 0
INFO 2018-10-26 14:25:57,584 basehttp 124 "POST /authorizations/ HTTP/1.1" 200 209
INFO 2018-10-26 14:28:22,799 basehttp 124 "POST /authorizations/ HTTP/1.1" 200 209
INFO 2018-10-26 14:36:54,627 basehttp 124 "OPTIONS /authorizations/ HTTP/1.1" 200 0
INFO 2018-10-26 14:37:14,341 basehttp 124 "POST /authorizations/ HTTP/1.1" 200 209
INFO 2018-10-26 20:45:37,625 basehttp 124 "GET /usernames/123456/count/ HTTP/1.1" 200 31
INFO 2018-10-26 20:45:40,662 basehttp 124 "GET /usernames/1234567/count/ HTTP/1.1" 200 32
INFO 2018-10-26 20:45:43,347 basehttp 124 "GET /usernames/12345678/count/ HTTP/1.1" 200 33
INFO 2018-10-26 20:45:53,311 basehttp 124 "GET /usernames/123456789/count/ HTTP/1.1" 200 34
INFO 2018-10-26 20:45:54,959 basehttp 124 "GET /usernames/1234567890/count/ HTTP/1.1" 200 35
WARNING 2018-10-26 21:16:51,373 base 152 Not Found: /oauth/qq/authorization/
WARNING 2018-10-26 21:16:51,374 basehttp 124 "GET /oauth/qq/authorization/?next=/ HTTP/1.1" 404 2909
WARNING 2018-10-26 21:16:52,739 base 152 Not Found: /oauth/qq/authorization/
WARNING 2018-10-26 21:16:52,739 basehttp 124 "GET /oauth/qq/authorization/?next=/ HTTP/1.1" 404 2909
WARNING 2018-10-26 21:16:52,959 base 152 Not Found: /oauth/qq/authorization/
WARNING 2018-10-26 21:16:52,959 basehttp 124 "GET /oauth/qq/authorization/?next=/ HTTP/1.1" 404 2909
WARNING 2018-10-26 21:16:53,132 base 152 Not Found: /oauth/qq/authorization/
WARNING 2018-10-26 21:16:53,133 basehttp 124 "GET /oauth/qq/authorization/?next=/ HTTP/1.1" 404 2909
WARNING 2018-10-26 21:16:53,308 base 152 Not Found: /oauth/qq/authorization/
WARNING 2018-10-26 21:16:53,309 basehttp 124 "GET /oauth/qq/authorization/?next=/ HTTP/1.1" 404 2909
WARNING 2018-10-26 21:17:19,903 base 152 Not Found: /oauth/qq/authorization/
WARNING 2018-10-26 21:17:19,904 basehttp 124 "GET /oauth/qq/authorization/?next=/ HTTP/1.1" 404 2909
INFO 2018-10-26 21:19:45,078 basehttp 124 "GET /oauth/qq/authorization/?next=/ HTTP/1.1" 200 141
INFO 2018-10-26 21:21:14,197 basehttp 124 "GET /oauth/qq/authorization/?next=/ HTTP/1.1" 200 195
WARNING 2018-10-26 21:21:37,648 base 152 Not Found: /oauth/qq/user/
WARNING 2018-10-26 21:21:37,649 basehttp 124 "GET /oauth/qq/user/?code=257A3C1B01DC4D25BC33EE34C4AF586D HTTP/1.1" 404 3085
INFO 2018-10-26 21:22:34,499 basehttp 124 "GET /oauth/qq/authorization/?next=/ HTTP/1.1" 200 195
ERROR 2018-10-26 21:22:55,606 exception 135 Internal Server Error: /oauth/qq/user/
Traceback (most recent call last):
  File "/Users/huangjianhao/Downloads/PythonProject/meiduo_mall/meiduo/meiduo/apps/oauth/views.py", line 55, in get
    qq_user = OAuthQQUser.objects.get(openid=openid)
  File "/Users/huangjianhao/.virtualenvs/django_py3_1.11/lib/python3.6/site-packages/django/db/models/manager.py", line 85, in manager_method
    return getattr(self.get_queryset(), name)(*args, **kwargs)
  File "/Users/huangjianhao/.virtualenvs/django_py3_1.11/lib/python3.6/site-packages/django/db/models/query.py", line 380, in get
    self.model._meta.object_name
oauth.models.DoesNotExist: OAuthQQUser matching query does not exist.

During handling of the above exception, another exception occurred:

Traceback (most recent call last):
  File "/Users/huangjianhao/.virtualenvs/django_py3_1.11/lib/python3.6/site-packages/django/core/handlers/exception.py", line 41, in inner
    response = get_response(request)
  File "/Users/huangjianhao/.virtualenvs/django_py3_1.11/lib/python3.6/site-packages/django/core/handlers/base.py", line 187, in _get_response
    response = self.process_exception_by_middleware(e, request)
  File "/Users/huangjianhao/.virtualenvs/django_py3_1.11/lib/python3.6/site-packages/django/core/handlers/base.py", line 185, in _get_response
    response = wrapped_callback(request, *callback_args, **callback_kwargs)
  File "/Users/huangjianhao/.virtualenvs/django_py3_1.11/lib/python3.6/site-packages/django/views/decorators/csrf.py", line 58, in wrapped_view
    return view_func(*args, **kwargs)
  File "/Users/huangjianhao/.virtualenvs/django_py3_1.11/lib/python3.6/site-packages/django/views/generic/base.py", line 68, in view
    return self.dispatch(request, *args, **kwargs)
  File "/Users/huangjianhao/.virtualenvs/django_py3_1.11/lib/python3.6/site-packages/rest_framework/views.py", line 483, in dispatch
    response = self.handle_exception(exc)
  File "/Users/huangjianhao/.virtualenvs/django_py3_1.11/lib/python3.6/site-packages/rest_framework/views.py", line 443, in handle_exception
    self.raise_uncaught_exception(exc)
  File "/Users/huangjianhao/.virtualenvs/django_py3_1.11/lib/python3.6/site-packages/rest_framework/views.py", line 480, in dispatch
    response = handler(request, *args, **kwargs)
  File "/Users/huangjianhao/Downloads/PythonProject/meiduo_mall/meiduo/meiduo/apps/oauth/views.py", line 58, in get
    token = oauth.generate_save_user_token(openid)
  File "/Users/huangjianhao/Downloads/PythonProject/meiduo_mall/meiduo/meiduo/apps/oauth/utils.py", line 90, in generate_save_user_token
    serializer = Serializer(dev.SECRET_KEY, expires_in = constants.SAVE_QQ_USER_TOKEN_EXPIRES)
  File "/Users/huangjianhao/.virtualenvs/django_py3_1.11/lib/python3.6/site-packages/rest_framework/serializers.py", line 118, in __init__
    super(BaseSerializer, self).__init__(**kwargs)
TypeError: __init__() got an unexpected keyword argument 'expires_in'
ERROR 2018-10-26 21:22:55,666 basehttp 124 "GET /oauth/qq/user/?code=E701F2671B3CBAF856000D741797A02D HTTP/1.1" 500 18337
INFO 2018-10-26 21:27:12,230 basehttp 124 "GET /oauth/qq/authorization/?next=/ HTTP/1.1" 200 195
ERROR 2018-10-26 21:27:23,500 exception 135 Internal Server Error: /oauth/qq/user/
Traceback (most recent call last):
  File "/Users/huangjianhao/Downloads/PythonProject/meiduo_mall/meiduo/meiduo/apps/oauth/views.py", line 55, in get
    qq_user = OAuthQQUser.objects.get(openid=openid)
  File "/Users/huangjianhao/.virtualenvs/django_py3_1.11/lib/python3.6/site-packages/django/db/models/manager.py", line 85, in manager_method
    return getattr(self.get_queryset(), name)(*args, **kwargs)
  File "/Users/huangjianhao/.virtualenvs/django_py3_1.11/lib/python3.6/site-packages/django/db/models/query.py", line 380, in get
    self.model._meta.object_name
oauth.models.DoesNotExist: OAuthQQUser matching query does not exist.

During handling of the above exception, another exception occurred:

Traceback (most recent call last):
  File "/Users/huangjianhao/.virtualenvs/django_py3_1.11/lib/python3.6/site-packages/django/core/handlers/exception.py", line 41, in inner
    response = get_response(request)
  File "/Users/huangjianhao/.virtualenvs/django_py3_1.11/lib/python3.6/site-packages/django/core/handlers/base.py", line 187, in _get_response
    response = self.process_exception_by_middleware(e, request)
  File "/Users/huangjianhao/.virtualenvs/django_py3_1.11/lib/python3.6/site-packages/django/core/handlers/base.py", line 185, in _get_response
    response = wrapped_callback(request, *callback_args, **callback_kwargs)
  File "/Users/huangjianhao/.virtualenvs/django_py3_1.11/lib/python3.6/site-packages/django/views/decorators/csrf.py", line 58, in wrapped_view
    return view_func(*args, **kwargs)
  File "/Users/huangjianhao/.virtualenvs/django_py3_1.11/lib/python3.6/site-packages/django/views/generic/base.py", line 68, in view
    return self.dispatch(request, *args, **kwargs)
  File "/Users/huangjianhao/.virtualenvs/django_py3_1.11/lib/python3.6/site-packages/rest_framework/views.py", line 483, in dispatch
    response = self.handle_exception(exc)
  File "/Users/huangjianhao/.virtualenvs/django_py3_1.11/lib/python3.6/site-packages/rest_framework/views.py", line 443, in handle_exception
    self.raise_uncaught_exception(exc)
  File "/Users/huangjianhao/.virtualenvs/django_py3_1.11/lib/python3.6/site-packages/rest_framework/views.py", line 480, in dispatch
    response = handler(request, *args, **kwargs)
  File "/Users/huangjianhao/Downloads/PythonProject/meiduo_mall/meiduo/meiduo/apps/oauth/views.py", line 58, in get
    token = oauth.generate_save_user_token(openid)
  File "/Users/huangjianhao/Downloads/PythonProject/meiduo_mall/meiduo/meiduo/apps/oauth/utils.py", line 90, in generate_save_user_token
    serializer = Serializer(dev.SECRET_KEY, expires_in=constants.SAVE_QQ_USER_TOKEN_EXPIRES)
  File "/Users/huangjianhao/.virtualenvs/django_py3_1.11/lib/python3.6/site-packages/rest_framework/serializers.py", line 118, in __init__
    super(BaseSerializer, self).__init__(**kwargs)
TypeError: __init__() got an unexpected keyword argument 'expires_in'
ERROR 2018-10-26 21:27:23,550 basehttp 124 "GET /oauth/qq/user/?code=9049294F1A697042F44A2F3E08BF008B HTTP/1.1" 500 18335
INFO 2018-10-26 21:40:15,816 basehttp 124 "GET /oauth/qq/authorization/?next=/ HTTP/1.1" 200 195
ERROR 2018-10-26 21:40:27,282 exception 135 Internal Server Error: /oauth/qq/user/
Traceback (most recent call last):
  File "/Users/huangjianhao/Downloads/PythonProject/meiduo_mall/meiduo/meiduo/apps/oauth/views.py", line 55, in get
    qq_user = OAuthQQUser.objects.get(openid=openid)
  File "/Users/huangjianhao/.virtualenvs/django_py3_1.11/lib/python3.6/site-packages/django/db/models/manager.py", line 85, in manager_method
    return getattr(self.get_queryset(), name)(*args, **kwargs)
  File "/Users/huangjianhao/.virtualenvs/django_py3_1.11/lib/python3.6/site-packages/django/db/models/query.py", line 380, in get
    self.model._meta.object_name
oauth.models.DoesNotExist: OAuthQQUser matching query does not exist.

During handling of the above exception, another exception occurred:

Traceback (most recent call last):
  File "/Users/huangjianhao/.virtualenvs/django_py3_1.11/lib/python3.6/site-packages/django/core/handlers/exception.py", line 41, in inner
    response = get_response(request)
  File "/Users/huangjianhao/.virtualenvs/django_py3_1.11/lib/python3.6/site-packages/django/core/handlers/base.py", line 187, in _get_response
    response = self.process_exception_by_middleware(e, request)
  File "/Users/huangjianhao/.virtualenvs/django_py3_1.11/lib/python3.6/site-packages/django/core/handlers/base.py", line 185, in _get_response
    response = wrapped_callback(request, *callback_args, **callback_kwargs)
  File "/Users/huangjianhao/.virtualenvs/django_py3_1.11/lib/python3.6/site-packages/django/views/decorators/csrf.py", line 58, in wrapped_view
    return view_func(*args, **kwargs)
  File "/Users/huangjianhao/.virtualenvs/django_py3_1.11/lib/python3.6/site-packages/django/views/generic/base.py", line 68, in view
    return self.dispatch(request, *args, **kwargs)
  File "/Users/huangjianhao/.virtualenvs/django_py3_1.11/lib/python3.6/site-packages/rest_framework/views.py", line 483, in dispatch
    response = self.handle_exception(exc)
  File "/Users/huangjianhao/.virtualenvs/django_py3_1.11/lib/python3.6/site-packages/rest_framework/views.py", line 443, in handle_exception
    self.raise_uncaught_exception(exc)
  File "/Users/huangjianhao/.virtualenvs/django_py3_1.11/lib/python3.6/site-packages/rest_framework/views.py", line 480, in dispatch
    response = handler(request, *args, **kwargs)
  File "/Users/huangjianhao/Downloads/PythonProject/meiduo_mall/meiduo/meiduo/apps/oauth/views.py", line 58, in get
    token = oauth.generate_save_user_token(openid)
  File "/Users/huangjianhao/Downloads/PythonProject/meiduo_mall/meiduo/meiduo/apps/oauth/utils.py", line 90, in generate_save_user_token
    serializer = Serializer(dev.SECRET_KEY, expires_in=constants.SAVE_QQ_USER_TOKEN_EXPIRES)
  File "/Users/huangjianhao/.virtualenvs/django_py3_1.11/lib/python3.6/site-packages/rest_framework/serializers.py", line 118, in __init__
    super(BaseSerializer, self).__init__(**kwargs)
TypeError: __init__() got an unexpected keyword argument 'expires_in'
ERROR 2018-10-26 21:40:27,331 basehttp 124 "GET /oauth/qq/user/?code=B709D2EABD3BF0A059E700F410D5ADA6 HTTP/1.1" 500 18335
INFO 2018-10-27 10:50:22,717 basehttp 124 "GET /oauth/qq/authorization/?next=/ HTTP/1.1" 200 195
INFO 2018-10-27 10:50:34,352 basehttp 124 "GET /oauth/qq/user/?code=AE687D6066B797A016D76067580B9D5E HTTP/1.1" 200 190
INFO 2018-10-27 11:01:12,669 basehttp 124 "GET /oauth/qq/authorization/?next=/ HTTP/1.1" 200 195
INFO 2018-10-27 11:01:21,053 basehttp 124 "GET /oauth/qq/user/?code=CAE6C8CFD7AFDF20AE97B9EBD1FB9D8C HTTP/1.1" 200 190
INFO 2018-10-28 09:05:09,088 basehttp 124 "GET /oauth/qq/authorization/?next=/ HTTP/1.1" 200 195
INFO 2018-10-28 09:05:10,466 basehttp 124 "GET /oauth/qq/authorization/?next=/ HTTP/1.1" 200 195
INFO 2018-10-28 09:05:15,993 basehttp 124 "GET /oauth/qq/authorization/?next=/ HTTP/1.1" 200 195
INFO 2018-10-28 09:07:31,812 basehttp 124 "GET /oauth/qq/authorization/?next=/ HTTP/1.1" 200 195
INFO 2018-10-28 09:08:12,138 basehttp 124 "GET /oauth/qq/authorization/?next=/ HTTP/1.1" 200 195
INFO 2018-10-28 09:08:57,119 basehttp 124 "GET /oauth/qq/authorization/?next=/ HTTP/1.1" 200 195
INFO 2018-10-28 09:09:17,318 basehttp 124 "GET /oauth/qq/authorization/?next=/ HTTP/1.1" 200 195
INFO 2018-10-28 09:10:05,961 basehttp 124 "GET /oauth/qq/authorization/?next=/ HTTP/1.1" 200 195
INFO 2018-10-28 09:10:13,770 basehttp 124 "GET /oauth/qq/authorization/?next=/ HTTP/1.1" 200 195
INFO 2018-10-28 09:10:32,787 basehttp 124 "GET /oauth/qq/user/?code=86DA248C6BF6DA48875E00065D3B737B HTTP/1.1" 200 190
INFO 2018-10-28 09:10:42,558 basehttp 124 "GET /sms_code/13590299759/ HTTP/1.1" 200 16
INFO 2018-10-28 09:10:43,583 tasks 29 发送验证码短信[正常][ mobile: 13590299759 ]
INFO 2018-10-28 09:10:58,317 basehttp 124 "OPTIONS /oauth/qq/user/ HTTP/1.1" 200 0
ERROR 2018-10-28 09:10:58,331 exceptions 26 [<oauth.views.QQAuthUserView object at 0x1119bacc0>] Got a `TypeError` when calling `User.objects.create()`. This may be because you have a writable field on the serializer class that is not a valid argument to `User.objects.create()`. You may need to make the field read-only, or override the OAuthQQUserSerializer.create() method to handle this correctly.
Original exception was:
 Traceback (most recent call last):
  File "/Users/huangjianhao/.virtualenvs/django_py3_1.11/lib/python3.6/site-packages/rest_framework/serializers.py", line 940, in create
    instance = ModelClass.objects.create(**validated_data)
  File "/Users/huangjianhao/.virtualenvs/django_py3_1.11/lib/python3.6/site-packages/django/db/models/manager.py", line 85, in manager_method
    return getattr(self.get_queryset(), name)(*args, **kwargs)
  File "/Users/huangjianhao/.virtualenvs/django_py3_1.11/lib/python3.6/site-packages/django/db/models/query.py", line 392, in create
    obj = self.model(**kwargs)
  File "/Users/huangjianhao/.virtualenvs/django_py3_1.11/lib/python3.6/site-packages/django/contrib/auth/base_user.py", line 68, in __init__
    super(AbstractBaseUser, self).__init__(*args, **kwargs)
  File "/Users/huangjianhao/.virtualenvs/django_py3_1.11/lib/python3.6/site-packages/django/db/models/base.py", line 573, in __init__
    raise TypeError("'%s' is an invalid keyword argument for this function" % list(kwargs)[0])
TypeError: 'sms_code' is an invalid keyword argument for this function

ERROR 2018-10-28 09:10:58,331 basehttp 124 "POST /oauth/qq/user/ HTTP/1.1" 507 35
INFO 2018-10-28 09:25:28,144 basehttp 124 "GET /oauth/qq/user/?code=8EB481C19E531EC91441F97CF9915D5D HTTP/1.1" 200 190
INFO 2018-10-28 09:25:34,507 basehttp 124 "GET /sms_code/13590299759/ HTTP/1.1" 200 16
INFO 2018-10-28 09:25:35,367 tasks 29 发送验证码短信[正常][ mobile: 13590299759 ]
INFO 2018-10-28 09:25:46,849 basehttp 124 "OPTIONS /oauth/qq/user/ HTTP/1.1" 200 0
ERROR 2018-10-28 09:25:46,857 exceptions 26 [<oauth.views.QQAuthUserView object at 0x1119bfd30>] Got a `TypeError` when calling `User.objects.create()`. This may be because you have a writable field on the serializer class that is not a valid argument to `User.objects.create()`. You may need to make the field read-only, or override the OAuthQQUserSerializer.create() method to handle this correctly.
Original exception was:
 Traceback (most recent call last):
  File "/Users/huangjianhao/.virtualenvs/django_py3_1.11/lib/python3.6/site-packages/rest_framework/serializers.py", line 940, in create
    instance = ModelClass.objects.create(**validated_data)
  File "/Users/huangjianhao/.virtualenvs/django_py3_1.11/lib/python3.6/site-packages/django/db/models/manager.py", line 85, in manager_method
    return getattr(self.get_queryset(), name)(*args, **kwargs)
  File "/Users/huangjianhao/.virtualenvs/django_py3_1.11/lib/python3.6/site-packages/django/db/models/query.py", line 392, in create
    obj = self.model(**kwargs)
  File "/Users/huangjianhao/.virtualenvs/django_py3_1.11/lib/python3.6/site-packages/django/contrib/auth/base_user.py", line 68, in __init__
    super(AbstractBaseUser, self).__init__(*args, **kwargs)
  File "/Users/huangjianhao/.virtualenvs/django_py3_1.11/lib/python3.6/site-packages/django/db/models/base.py", line 573, in __init__
    raise TypeError("'%s' is an invalid keyword argument for this function" % list(kwargs)[0])
TypeError: 'sms_code' is an invalid keyword argument for this function

ERROR 2018-10-28 09:25:46,858 basehttp 124 "POST /oauth/qq/user/ HTTP/1.1" 507 35
ERROR 2018-10-28 09:33:25,606 exceptions 26 [<oauth.views.QQAuthUserView object at 0x111cc6208>] Got a `TypeError` when calling `User.objects.create()`. This may be because you have a writable field on the serializer class that is not a valid argument to `User.objects.create()`. You may need to make the field read-only, or override the OAuthQQUserSerializer.create() method to handle this correctly.
Original exception was:
 Traceback (most recent call last):
  File "/Users/huangjianhao/.virtualenvs/django_py3_1.11/lib/python3.6/site-packages/rest_framework/serializers.py", line 940, in create
    instance = ModelClass.objects.create(**validated_data)
  File "/Users/huangjianhao/.virtualenvs/django_py3_1.11/lib/python3.6/site-packages/django/db/models/manager.py", line 85, in manager_method
    return getattr(self.get_queryset(), name)(*args, **kwargs)
  File "/Users/huangjianhao/.virtualenvs/django_py3_1.11/lib/python3.6/site-packages/django/db/models/query.py", line 392, in create
    obj = self.model(**kwargs)
  File "/Users/huangjianhao/.virtualenvs/django_py3_1.11/lib/python3.6/site-packages/django/contrib/auth/base_user.py", line 68, in __init__
    super(AbstractBaseUser, self).__init__(*args, **kwargs)
  File "/Users/huangjianhao/.virtualenvs/django_py3_1.11/lib/python3.6/site-packages/django/db/models/base.py", line 573, in __init__
    raise TypeError("'%s' is an invalid keyword argument for this function" % list(kwargs)[0])
TypeError: 'sms_code' is an invalid keyword argument for this function

ERROR 2018-10-28 09:33:25,611 basehttp 124 "POST /oauth/qq/user/ HTTP/1.1" 507 35
ERROR 2018-10-28 09:33:36,962 exceptions 26 [<oauth.views.QQAuthUserView object at 0x111eb2ac8>] Got a `TypeError` when calling `User.objects.create()`. This may be because you have a writable field on the serializer class that is not a valid argument to `User.objects.create()`. You may need to make the field read-only, or override the OAuthQQUserSerializer.create() method to handle this correctly.
Original exception was:
 Traceback (most recent call last):
  File "/Users/huangjianhao/.virtualenvs/django_py3_1.11/lib/python3.6/site-packages/rest_framework/serializers.py", line 940, in create
    instance = ModelClass.objects.create(**validated_data)
  File "/Users/huangjianhao/.virtualenvs/django_py3_1.11/lib/python3.6/site-packages/django/db/models/manager.py", line 85, in manager_method
    return getattr(self.get_queryset(), name)(*args, **kwargs)
  File "/Users/huangjianhao/.virtualenvs/django_py3_1.11/lib/python3.6/site-packages/django/db/models/query.py", line 392, in create
    obj = self.model(**kwargs)
  File "/Users/huangjianhao/.virtualenvs/django_py3_1.11/lib/python3.6/site-packages/django/contrib/auth/base_user.py", line 68, in __init__
    super(AbstractBaseUser, self).__init__(*args, **kwargs)
  File "/Users/huangjianhao/.virtualenvs/django_py3_1.11/lib/python3.6/site-packages/django/db/models/base.py", line 573, in __init__
    raise TypeError("'%s' is an invalid keyword argument for this function" % list(kwargs)[0])
TypeError: 'sms_code' is an invalid keyword argument for this function

ERROR 2018-10-28 09:33:36,966 basehttp 124 "POST /oauth/qq/user/ HTTP/1.1" 507 35
ERROR 2018-10-28 09:33:45,712 exceptions 26 [<oauth.views.QQAuthUserView object at 0x111f40588>] Got a `TypeError` when calling `User.objects.create()`. This may be because you have a writable field on the serializer class that is not a valid argument to `User.objects.create()`. You may need to make the field read-only, or override the OAuthQQUserSerializer.create() method to handle this correctly.
Original exception was:
 Traceback (most recent call last):
  File "/Users/huangjianhao/.virtualenvs/django_py3_1.11/lib/python3.6/site-packages/rest_framework/serializers.py", line 940, in create
    instance = ModelClass.objects.create(**validated_data)
  File "/Users/huangjianhao/.virtualenvs/django_py3_1.11/lib/python3.6/site-packages/django/db/models/manager.py", line 85, in manager_method
    return getattr(self.get_queryset(), name)(*args, **kwargs)
  File "/Users/huangjianhao/.virtualenvs/django_py3_1.11/lib/python3.6/site-packages/django/db/models/query.py", line 392, in create
    obj = self.model(**kwargs)
  File "/Users/huangjianhao/.virtualenvs/django_py3_1.11/lib/python3.6/site-packages/django/contrib/auth/base_user.py", line 68, in __init__
    super(AbstractBaseUser, self).__init__(*args, **kwargs)
  File "/Users/huangjianhao/.virtualenvs/django_py3_1.11/lib/python3.6/site-packages/django/db/models/base.py", line 573, in __init__
    raise TypeError("'%s' is an invalid keyword argument for this function" % list(kwargs)[0])
TypeError: 'sms_code' is an invalid keyword argument for this function

ERROR 2018-10-28 09:33:45,715 basehttp 124 "POST /oauth/qq/user/ HTTP/1.1" 507 35
ERROR 2018-10-28 09:37:09,296 exceptions 26 [<oauth.views.QQAuthUserView object at 0x111f40550>] Got a `TypeError` when calling `User.objects.create()`. This may be because you have a writable field on the serializer class that is not a valid argument to `User.objects.create()`. You may need to make the field read-only, or override the OAuthQQUserSerializer.create() method to handle this correctly.
Original exception was:
 Traceback (most recent call last):
  File "/Users/huangjianhao/.virtualenvs/django_py3_1.11/lib/python3.6/site-packages/rest_framework/serializers.py", line 940, in create
    instance = ModelClass.objects.create(**validated_data)
  File "/Users/huangjianhao/.virtualenvs/django_py3_1.11/lib/python3.6/site-packages/django/db/models/manager.py", line 85, in manager_method
    return getattr(self.get_queryset(), name)(*args, **kwargs)
  File "/Users/huangjianhao/.virtualenvs/django_py3_1.11/lib/python3.6/site-packages/django/db/models/query.py", line 392, in create
    obj = self.model(**kwargs)
  File "/Users/huangjianhao/.virtualenvs/django_py3_1.11/lib/python3.6/site-packages/django/contrib/auth/base_user.py", line 68, in __init__
    super(AbstractBaseUser, self).__init__(*args, **kwargs)
  File "/Users/huangjianhao/.virtualenvs/django_py3_1.11/lib/python3.6/site-packages/django/db/models/base.py", line 573, in __init__
    raise TypeError("'%s' is an invalid keyword argument for this function" % list(kwargs)[0])
TypeError: 'sms_code' is an invalid keyword argument for this function

ERROR 2018-10-28 09:37:09,303 basehttp 124 "POST /oauth/qq/user/ HTTP/1.1" 507 35
INFO 2018-10-28 09:37:49,688 basehttp 124 "OPTIONS /oauth/qq/user/ HTTP/1.1" 200 0
ERROR 2018-10-28 09:37:55,754 exceptions 26 [<oauth.views.QQAuthUserView object at 0x111f570b8>] Got a `TypeError` when calling `User.objects.create()`. This may be because you have a writable field on the serializer class that is not a valid argument to `User.objects.create()`. You may need to make the field read-only, or override the OAuthQQUserSerializer.create() method to handle this correctly.
Original exception was:
 Traceback (most recent call last):
  File "/Users/huangjianhao/.virtualenvs/django_py3_1.11/lib/python3.6/site-packages/rest_framework/serializers.py", line 940, in create
    instance = ModelClass.objects.create(**validated_data)
  File "/Users/huangjianhao/.virtualenvs/django_py3_1.11/lib/python3.6/site-packages/django/db/models/manager.py", line 85, in manager_method
    return getattr(self.get_queryset(), name)(*args, **kwargs)
  File "/Users/huangjianhao/.virtualenvs/django_py3_1.11/lib/python3.6/site-packages/django/db/models/query.py", line 392, in create
    obj = self.model(**kwargs)
  File "/Users/huangjianhao/.virtualenvs/django_py3_1.11/lib/python3.6/site-packages/django/contrib/auth/base_user.py", line 68, in __init__
    super(AbstractBaseUser, self).__init__(*args, **kwargs)
  File "/Users/huangjianhao/.virtualenvs/django_py3_1.11/lib/python3.6/site-packages/django/db/models/base.py", line 573, in __init__
    raise TypeError("'%s' is an invalid keyword argument for this function" % list(kwargs)[0])
TypeError: 'sms_code' is an invalid keyword argument for this function

ERROR 2018-10-28 09:37:55,760 basehttp 124 "POST /oauth/qq/user/ HTTP/1.1" 507 35
ERROR 2018-10-28 09:41:23,793 exceptions 26 [<oauth.views.QQAuthUserView object at 0x1115c9f60>] Got a `TypeError` when calling `User.objects.create()`. This may be because you have a writable field on the serializer class that is not a valid argument to `User.objects.create()`. You may need to make the field read-only, or override the OAuthQQUserSerializer.create() method to handle this correctly.
Original exception was:
 Traceback (most recent call last):
  File "/Users/huangjianhao/.virtualenvs/django_py3_1.11/lib/python3.6/site-packages/rest_framework/serializers.py", line 940, in create
    instance = ModelClass.objects.create(**validated_data)
  File "/Users/huangjianhao/.virtualenvs/django_py3_1.11/lib/python3.6/site-packages/django/db/models/manager.py", line 85, in manager_method
    return getattr(self.get_queryset(), name)(*args, **kwargs)
  File "/Users/huangjianhao/.virtualenvs/django_py3_1.11/lib/python3.6/site-packages/django/db/models/query.py", line 392, in create
    obj = self.model(**kwargs)
  File "/Users/huangjianhao/.virtualenvs/django_py3_1.11/lib/python3.6/site-packages/django/contrib/auth/base_user.py", line 68, in __init__
    super(AbstractBaseUser, self).__init__(*args, **kwargs)
  File "/Users/huangjianhao/.virtualenvs/django_py3_1.11/lib/python3.6/site-packages/django/db/models/base.py", line 573, in __init__
    raise TypeError("'%s' is an invalid keyword argument for this function" % list(kwargs)[0])
TypeError: 'sms_code' is an invalid keyword argument for this function

ERROR 2018-10-28 09:41:23,794 basehttp 124 "POST /oauth/qq/user/ HTTP/1.1" 507 35
INFO 2018-10-28 09:50:42,188 basehttp 124 "OPTIONS /oauth/qq/user/ HTTP/1.1" 200 0
ERROR 2018-10-28 09:50:42,213 exceptions 26 [<oauth.views.QQAuthUserView object at 0x110d912e8>] Got a `TypeError` when calling `User.objects.create()`. This may be because you have a writable field on the serializer class that is not a valid argument to `User.objects.create()`. You may need to make the field read-only, or override the OAuthQQUserSerializer.create() method to handle this correctly.
Original exception was:
 Traceback (most recent call last):
  File "/Users/huangjianhao/.virtualenvs/django_py3_1.11/lib/python3.6/site-packages/rest_framework/serializers.py", line 940, in create
    instance = ModelClass.objects.create(**validated_data)
  File "/Users/huangjianhao/.virtualenvs/django_py3_1.11/lib/python3.6/site-packages/django/db/models/manager.py", line 85, in manager_method
    return getattr(self.get_queryset(), name)(*args, **kwargs)
  File "/Users/huangjianhao/.virtualenvs/django_py3_1.11/lib/python3.6/site-packages/django/db/models/query.py", line 392, in create
    obj = self.model(**kwargs)
  File "/Users/huangjianhao/.virtualenvs/django_py3_1.11/lib/python3.6/site-packages/django/contrib/auth/base_user.py", line 68, in __init__
    super(AbstractBaseUser, self).__init__(*args, **kwargs)
  File "/Users/huangjianhao/.virtualenvs/django_py3_1.11/lib/python3.6/site-packages/django/db/models/base.py", line 573, in __init__
    raise TypeError("'%s' is an invalid keyword argument for this function" % list(kwargs)[0])
TypeError: 'sms_code' is an invalid keyword argument for this function

ERROR 2018-10-28 09:50:42,214 basehttp 124 "POST /oauth/qq/user/ HTTP/1.1" 507 35
ERROR 2018-10-28 10:00:40,480 exceptions 26 [<oauth.views.QQAuthUserView object at 0x110bd2e80>] Got a `TypeError` when calling `User.objects.create()`. This may be because you have a writable field on the serializer class that is not a valid argument to `User.objects.create()`. You may need to make the field read-only, or override the OAuthQQUserSerializer.create() method to handle this correctly.
Original exception was:
 Traceback (most recent call last):
  File "/Users/huangjianhao/.virtualenvs/django_py3_1.11/lib/python3.6/site-packages/rest_framework/serializers.py", line 940, in create
    instance = ModelClass.objects.create(**validated_data)
  File "/Users/huangjianhao/.virtualenvs/django_py3_1.11/lib/python3.6/site-packages/django/db/models/manager.py", line 85, in manager_method
    return getattr(self.get_queryset(), name)(*args, **kwargs)
  File "/Users/huangjianhao/.virtualenvs/django_py3_1.11/lib/python3.6/site-packages/django/db/models/query.py", line 392, in create
    obj = self.model(**kwargs)
  File "/Users/huangjianhao/.virtualenvs/django_py3_1.11/lib/python3.6/site-packages/django/contrib/auth/base_user.py", line 68, in __init__
    super(AbstractBaseUser, self).__init__(*args, **kwargs)
  File "/Users/huangjianhao/.virtualenvs/django_py3_1.11/lib/python3.6/site-packages/django/db/models/base.py", line 573, in __init__
    raise TypeError("'%s' is an invalid keyword argument for this function" % list(kwargs)[0])
TypeError: 'sms_code' is an invalid keyword argument for this function

ERROR 2018-10-28 10:00:40,481 basehttp 124 "POST /oauth/qq/user/ HTTP/1.1" 507 35
INFO 2018-10-28 10:03:19,765 basehttp 124 "OPTIONS /oauth/qq/user/ HTTP/1.1" 200 0
ERROR 2018-10-28 10:03:19,802 exceptions 26 [<oauth.views.QQAuthUserView object at 0x111645320>] Got a `TypeError` when calling `User.objects.create()`. This may be because you have a writable field on the serializer class that is not a valid argument to `User.objects.create()`. You may need to make the field read-only, or override the OAuthQQUserSerializer.create() method to handle this correctly.
Original exception was:
 Traceback (most recent call last):
  File "/Users/huangjianhao/.virtualenvs/django_py3_1.11/lib/python3.6/site-packages/rest_framework/serializers.py", line 940, in create
    instance = ModelClass.objects.create(**validated_data)
  File "/Users/huangjianhao/.virtualenvs/django_py3_1.11/lib/python3.6/site-packages/django/db/models/manager.py", line 85, in manager_method
    return getattr(self.get_queryset(), name)(*args, **kwargs)
  File "/Users/huangjianhao/.virtualenvs/django_py3_1.11/lib/python3.6/site-packages/django/db/models/query.py", line 392, in create
    obj = self.model(**kwargs)
  File "/Users/huangjianhao/.virtualenvs/django_py3_1.11/lib/python3.6/site-packages/django/contrib/auth/base_user.py", line 68, in __init__
    super(AbstractBaseUser, self).__init__(*args, **kwargs)
  File "/Users/huangjianhao/.virtualenvs/django_py3_1.11/lib/python3.6/site-packages/django/db/models/base.py", line 573, in __init__
    raise TypeError("'%s' is an invalid keyword argument for this function" % list(kwargs)[0])
TypeError: 'sms_code' is an invalid keyword argument for this function

ERROR 2018-10-28 10:03:19,803 basehttp 124 "POST /oauth/qq/user/ HTTP/1.1" 507 35
ERROR 2018-10-28 10:11:10,042 exceptions 26 [<oauth.views.QQAuthUserView object at 0x11153db00>] Got a `TypeError` when calling `User.objects.create()`. This may be because you have a writable field on the serializer class that is not a valid argument to `User.objects.create()`. You may need to make the field read-only, or override the OAuthQQUserSerializer.create() method to handle this correctly.
Original exception was:
 Traceback (most recent call last):
  File "/Users/huangjianhao/.virtualenvs/django_py3_1.11/lib/python3.6/site-packages/rest_framework/serializers.py", line 940, in create
    instance = ModelClass.objects.create(**validated_data)
  File "/Users/huangjianhao/.virtualenvs/django_py3_1.11/lib/python3.6/site-packages/django/db/models/manager.py", line 85, in manager_method
    return getattr(self.get_queryset(), name)(*args, **kwargs)
  File "/Users/huangjianhao/.virtualenvs/django_py3_1.11/lib/python3.6/site-packages/django/db/models/query.py", line 392, in create
    obj = self.model(**kwargs)
  File "/Users/huangjianhao/.virtualenvs/django_py3_1.11/lib/python3.6/site-packages/django/contrib/auth/base_user.py", line 68, in __init__
    super(AbstractBaseUser, self).__init__(*args, **kwargs)
  File "/Users/huangjianhao/.virtualenvs/django_py3_1.11/lib/python3.6/site-packages/django/db/models/base.py", line 573, in __init__
    raise TypeError("'%s' is an invalid keyword argument for this function" % list(kwargs)[0])
TypeError: 'sms_code' is an invalid keyword argument for this function

ERROR 2018-10-28 10:11:10,043 basehttp 124 "POST /oauth/qq/user/ HTTP/1.1" 507 35
ERROR 2018-10-28 10:11:33,456 exceptions 26 [<oauth.views.QQAuthUserView object at 0x1112df710>] Got a `TypeError` when calling `User.objects.create()`. This may be because you have a writable field on the serializer class that is not a valid argument to `User.objects.create()`. You may need to make the field read-only, or override the OAuthQQUserSerializer.create() method to handle this correctly.
Original exception was:
 Traceback (most recent call last):
  File "/Users/huangjianhao/.virtualenvs/django_py3_1.11/lib/python3.6/site-packages/rest_framework/serializers.py", line 940, in create
    instance = ModelClass.objects.create(**validated_data)
  File "/Users/huangjianhao/.virtualenvs/django_py3_1.11/lib/python3.6/site-packages/django/db/models/manager.py", line 85, in manager_method
    return getattr(self.get_queryset(), name)(*args, **kwargs)
  File "/Users/huangjianhao/.virtualenvs/django_py3_1.11/lib/python3.6/site-packages/django/db/models/query.py", line 392, in create
    obj = self.model(**kwargs)
  File "/Users/huangjianhao/.virtualenvs/django_py3_1.11/lib/python3.6/site-packages/django/contrib/auth/base_user.py", line 68, in __init__
    super(AbstractBaseUser, self).__init__(*args, **kwargs)
  File "/Users/huangjianhao/.virtualenvs/django_py3_1.11/lib/python3.6/site-packages/django/db/models/base.py", line 573, in __init__
    raise TypeError("'%s' is an invalid keyword argument for this function" % list(kwargs)[0])
TypeError: 'sms_code' is an invalid keyword argument for this function

ERROR 2018-10-28 10:11:33,457 basehttp 124 "POST /oauth/qq/user/ HTTP/1.1" 507 35
ERROR 2018-10-28 10:11:52,038 exceptions 26 [<oauth.views.QQAuthUserView object at 0x10fe20e48>] Got a `TypeError` when calling `User.objects.create()`. This may be because you have a writable field on the serializer class that is not a valid argument to `User.objects.create()`. You may need to make the field read-only, or override the OAuthQQUserSerializer.create() method to handle this correctly.
Original exception was:
 Traceback (most recent call last):
  File "/Users/huangjianhao/.virtualenvs/django_py3_1.11/lib/python3.6/site-packages/rest_framework/serializers.py", line 940, in create
    instance = ModelClass.objects.create(**validated_data)
  File "/Users/huangjianhao/.virtualenvs/django_py3_1.11/lib/python3.6/site-packages/django/db/models/manager.py", line 85, in manager_method
    return getattr(self.get_queryset(), name)(*args, **kwargs)
  File "/Users/huangjianhao/.virtualenvs/django_py3_1.11/lib/python3.6/site-packages/django/db/models/query.py", line 392, in create
    obj = self.model(**kwargs)
  File "/Users/huangjianhao/.virtualenvs/django_py3_1.11/lib/python3.6/site-packages/django/contrib/auth/base_user.py", line 68, in __init__
    super(AbstractBaseUser, self).__init__(*args, **kwargs)
  File "/Users/huangjianhao/.virtualenvs/django_py3_1.11/lib/python3.6/site-packages/django/db/models/base.py", line 573, in __init__
    raise TypeError("'%s' is an invalid keyword argument for this function" % list(kwargs)[0])
TypeError: 'sms_code' is an invalid keyword argument for this function

ERROR 2018-10-28 10:11:52,039 basehttp 124 "POST /oauth/qq/user/ HTTP/1.1" 507 35
INFO 2018-10-28 10:42:49,241 basehttp 124 "OPTIONS /oauth/qq/user/ HTTP/1.1" 200 0
ERROR 2018-10-28 10:42:49,272 exceptions 26 [<oauth.views.QQAuthUserView object at 0x10fd41358>] The field 'access_token' was declared on serializer OAuthQQUserSerializer, but has not been included in the 'fields' option.
ERROR 2018-10-28 10:42:49,272 basehttp 124 "POST /oauth/qq/user/ HTTP/1.1" 507 35
ERROR 2018-10-28 10:43:13,050 exceptions 26 [<oauth.views.QQAuthUserView object at 0x1115a9748>] The field 'sms_code' was declared on serializer OAuthQQUserSerializer, but has not been included in the 'fields' option.
ERROR 2018-10-28 10:43:13,051 basehttp 124 "POST /oauth/qq/user/ HTTP/1.1" 507 35
ERROR 2018-10-28 10:43:45,619 exceptions 26 [<oauth.views.QQAuthUserView object at 0x10fe675f8>] Got a `TypeError` when calling `User.objects.create()`. This may be because you have a writable field on the serializer class that is not a valid argument to `User.objects.create()`. You may need to make the field read-only, or override the OAuthQQUserSerializer.create() method to handle this correctly.
Original exception was:
 Traceback (most recent call last):
  File "/Users/huangjianhao/.virtualenvs/django_py3_1.11/lib/python3.6/site-packages/rest_framework/serializers.py", line 940, in create
    instance = ModelClass.objects.create(**validated_data)
  File "/Users/huangjianhao/.virtualenvs/django_py3_1.11/lib/python3.6/site-packages/django/db/models/manager.py", line 85, in manager_method
    return getattr(self.get_queryset(), name)(*args, **kwargs)
  File "/Users/huangjianhao/.virtualenvs/django_py3_1.11/lib/python3.6/site-packages/django/db/models/query.py", line 392, in create
    obj = self.model(**kwargs)
  File "/Users/huangjianhao/.virtualenvs/django_py3_1.11/lib/python3.6/site-packages/django/contrib/auth/base_user.py", line 68, in __init__
    super(AbstractBaseUser, self).__init__(*args, **kwargs)
  File "/Users/huangjianhao/.virtualenvs/django_py3_1.11/lib/python3.6/site-packages/django/db/models/base.py", line 573, in __init__
    raise TypeError("'%s' is an invalid keyword argument for this function" % list(kwargs)[0])
TypeError: 'sms_code' is an invalid keyword argument for this function

ERROR 2018-10-28 10:43:45,620 basehttp 124 "POST /oauth/qq/user/ HTTP/1.1" 507 35
ERROR 2018-10-28 10:46:29,434 exceptions 26 [<oauth.views.QQAuthUserView object at 0x110aed6d8>] Got a `TypeError` when calling `User.objects.create()`. This may be because you have a writable field on the serializer class that is not a valid argument to `User.objects.create()`. You may need to make the field read-only, or override the OAuthQQUserSerializer.create() method to handle this correctly.
Original exception was:
 Traceback (most recent call last):
  File "/Users/huangjianhao/.virtualenvs/django_py3_1.11/lib/python3.6/site-packages/rest_framework/serializers.py", line 940, in create
    instance = ModelClass.objects.create(**validated_data)
  File "/Users/huangjianhao/.virtualenvs/django_py3_1.11/lib/python3.6/site-packages/django/db/models/manager.py", line 85, in manager_method
    return getattr(self.get_queryset(), name)(*args, **kwargs)
  File "/Users/huangjianhao/.virtualenvs/django_py3_1.11/lib/python3.6/site-packages/django/db/models/query.py", line 392, in create
    obj = self.model(**kwargs)
  File "/Users/huangjianhao/.virtualenvs/django_py3_1.11/lib/python3.6/site-packages/django/contrib/auth/base_user.py", line 68, in __init__
    super(AbstractBaseUser, self).__init__(*args, **kwargs)
  File "/Users/huangjianhao/.virtualenvs/django_py3_1.11/lib/python3.6/site-packages/django/db/models/base.py", line 573, in __init__
    raise TypeError("'%s' is an invalid keyword argument for this function" % list(kwargs)[0])
TypeError: 'access_token' is an invalid keyword argument for this function

ERROR 2018-10-28 10:46:29,435 basehttp 124 "POST /oauth/qq/user/ HTTP/1.1" 507 35
ERROR 2018-10-28 10:46:55,138 exceptions 26 [<oauth.views.QQAuthUserView object at 0x111409fd0>] (1062, "Duplicate entry '13590299759' for key 'mobile'")
ERROR 2018-10-28 10:46:55,139 basehttp 124 "POST /oauth/qq/user/ HTTP/1.1" 507 35
ERROR 2018-10-28 10:48:49,023 exceptions 26 [<oauth.views.QQAuthUserView object at 0x1114861d0>] Got a `TypeError` when calling `User.objects.create()`. This may be because you have a writable field on the serializer class that is not a valid argument to `User.objects.create()`. You may need to make the field read-only, or override the OAuthQQUserSerializer.create() method to handle this correctly.
Original exception was:
 Traceback (most recent call last):
  File "/Users/huangjianhao/.virtualenvs/django_py3_1.11/lib/python3.6/site-packages/rest_framework/serializers.py", line 940, in create
    instance = ModelClass.objects.create(**validated_data)
  File "/Users/huangjianhao/.virtualenvs/django_py3_1.11/lib/python3.6/site-packages/django/db/models/manager.py", line 85, in manager_method
    return getattr(self.get_queryset(), name)(*args, **kwargs)
  File "/Users/huangjianhao/.virtualenvs/django_py3_1.11/lib/python3.6/site-packages/django/db/models/query.py", line 392, in create
    obj = self.model(**kwargs)
  File "/Users/huangjianhao/.virtualenvs/django_py3_1.11/lib/python3.6/site-packages/django/contrib/auth/base_user.py", line 68, in __init__
    super(AbstractBaseUser, self).__init__(*args, **kwargs)
  File "/Users/huangjianhao/.virtualenvs/django_py3_1.11/lib/python3.6/site-packages/django/db/models/base.py", line 573, in __init__
    raise TypeError("'%s' is an invalid keyword argument for this function" % list(kwargs)[0])
TypeError: 'sms_code' is an invalid keyword argument for this function

ERROR 2018-10-28 10:48:49,024 basehttp 124 "POST /oauth/qq/user/ HTTP/1.1" 507 35
ERROR 2018-10-28 10:52:14,583 exceptions 26 [<oauth.views.QQAuthUserView object at 0x110ea93c8>] (1062, "Duplicate entry '13590299759' for key 'mobile'")
ERROR 2018-10-28 10:52:14,584 basehttp 124 "POST /oauth/qq/user/ HTTP/1.1" 507 35
INFO 2018-10-28 10:55:06,703 basehttp 124 "OPTIONS /oauth/qq/user/ HTTP/1.1" 200 0
ERROR 2018-10-28 10:55:10,710 exceptions 26 [<oauth.views.QQAuthUserView object at 0x111d182b0>] (1062, "Duplicate entry '13590299759' for key 'mobile'")
ERROR 2018-10-28 10:55:10,712 basehttp 124 "POST /oauth/qq/user/ HTTP/1.1" 507 35
ERROR 2018-10-28 10:57:06,422 exceptions 26 [<oauth.views.QQAuthUserView object at 0x1114b5be0>] (1062, "Duplicate entry '13590299759' for key 'mobile'")
ERROR 2018-10-28 10:57:06,423 basehttp 124 "POST /oauth/qq/user/ HTTP/1.1" 507 35
ERROR 2018-10-28 10:58:35,373 exceptions 26 [<oauth.views.QQAuthUserView object at 0x11149eda0>] (1062, "Duplicate entry '13590299759' for key 'mobile'")
ERROR 2018-10-28 10:58:35,374 basehttp 124 "POST /oauth/qq/user/ HTTP/1.1" 507 35
ERROR 2018-10-28 11:00:21,183 exceptions 26 [<oauth.views.QQAuthUserView object at 0x11074bba8>] (1062, "Duplicate entry '13590299759' for key 'mobile'")
ERROR 2018-10-28 11:00:21,185 basehttp 124 "POST /oauth/qq/user/ HTTP/1.1" 507 35
ERROR 2018-10-28 11:00:47,335 exceptions 26 [<oauth.views.QQAuthUserView object at 0x111cd6ef0>] (1062, "Duplicate entry '13590299759' for key 'mobile'")
ERROR 2018-10-28 11:00:47,340 basehttp 124 "POST /oauth/qq/user/ HTTP/1.1" 507 35
ERROR 2018-10-28 11:01:23,116 exceptions 26 [<oauth.views.QQAuthUserView object at 0x11149e320>] (1062, "Duplicate entry '13590299759' for key 'mobile'")
ERROR 2018-10-28 11:01:23,117 basehttp 124 "POST /oauth/qq/user/ HTTP/1.1" 507 35
ERROR 2018-10-28 11:01:23,235 exceptions 26 [<oauth.views.QQAuthUserView object at 0x111739518>] (1062, "Duplicate entry '13590299759' for key 'mobile'")
ERROR 2018-10-28 11:01:23,236 basehttp 124 "POST /oauth/qq/user/ HTTP/1.1" 507 35
ERROR 2018-10-28 11:02:53,249 exceptions 26 [<oauth.views.QQAuthUserView object at 0x1113591d0>] Got a `TypeError` when calling `User.objects.create()`. This may be because you have a writable field on the serializer class that is not a valid argument to `User.objects.create()`. You may need to make the field read-only, or override the OAuthQQUserSerializer.create() method to handle this correctly.
Original exception was:
 Traceback (most recent call last):
  File "/Users/huangjianhao/.virtualenvs/django_py3_1.11/lib/python3.6/site-packages/rest_framework/serializers.py", line 940, in create
    instance = ModelClass.objects.create(**validated_data)
  File "/Users/huangjianhao/.virtualenvs/django_py3_1.11/lib/python3.6/site-packages/django/db/models/manager.py", line 85, in manager_method
    return getattr(self.get_queryset(), name)(*args, **kwargs)
  File "/Users/huangjianhao/.virtualenvs/django_py3_1.11/lib/python3.6/site-packages/django/db/models/query.py", line 392, in create
    obj = self.model(**kwargs)
  File "/Users/huangjianhao/.virtualenvs/django_py3_1.11/lib/python3.6/site-packages/django/contrib/auth/base_user.py", line 68, in __init__
    super(AbstractBaseUser, self).__init__(*args, **kwargs)
  File "/Users/huangjianhao/.virtualenvs/django_py3_1.11/lib/python3.6/site-packages/django/db/models/base.py", line 573, in __init__
    raise TypeError("'%s' is an invalid keyword argument for this function" % list(kwargs)[0])
TypeError: 'sms_code' is an invalid keyword argument for this function

ERROR 2018-10-28 11:02:53,249 basehttp 124 "POST /oauth/qq/user/ HTTP/1.1" 507 35
INFO 2018-10-28 11:07:40,309 basehttp 124 "OPTIONS /oauth/qq/user/ HTTP/1.1" 200 0
ERROR 2018-10-28 11:07:40,408 exceptions 26 [<oauth.views.QQAuthUserView object at 0x111dc2cc0>] Got a `TypeError` when calling `User.objects.create()`. This may be because you have a writable field on the serializer class that is not a valid argument to `User.objects.create()`. You may need to make the field read-only, or override the OAuthQQUserSerializer.create() method to handle this correctly.
Original exception was:
 Traceback (most recent call last):
  File "/Users/huangjianhao/.virtualenvs/django_py3_1.11/lib/python3.6/site-packages/rest_framework/serializers.py", line 940, in create
    instance = ModelClass.objects.create(**validated_data)
  File "/Users/huangjianhao/.virtualenvs/django_py3_1.11/lib/python3.6/site-packages/django/db/models/manager.py", line 85, in manager_method
    return getattr(self.get_queryset(), name)(*args, **kwargs)
  File "/Users/huangjianhao/.virtualenvs/django_py3_1.11/lib/python3.6/site-packages/django/db/models/query.py", line 392, in create
    obj = self.model(**kwargs)
  File "/Users/huangjianhao/.virtualenvs/django_py3_1.11/lib/python3.6/site-packages/django/contrib/auth/base_user.py", line 68, in __init__
    super(AbstractBaseUser, self).__init__(*args, **kwargs)
  File "/Users/huangjianhao/.virtualenvs/django_py3_1.11/lib/python3.6/site-packages/django/db/models/base.py", line 573, in __init__
    raise TypeError("'%s' is an invalid keyword argument for this function" % list(kwargs)[0])
TypeError: 'sms_code' is an invalid keyword argument for this function

ERROR 2018-10-28 11:07:40,412 basehttp 124 "POST /oauth/qq/user/ HTTP/1.1" 507 35
ERROR 2018-10-28 11:13:49,896 exceptions 26 [<oauth.views.QQAuthUserView object at 0x10f9a7940>] Got a `TypeError` when calling `User.objects.create()`. This may be because you have a writable field on the serializer class that is not a valid argument to `User.objects.create()`. You may need to make the field read-only, or override the OAuthQQUserSerializer.create() method to handle this correctly.
Original exception was:
 Traceback (most recent call last):
  File "/Users/huangjianhao/.virtualenvs/django_py3_1.11/lib/python3.6/site-packages/rest_framework/serializers.py", line 940, in create
    instance = ModelClass.objects.create(**validated_data)
  File "/Users/huangjianhao/.virtualenvs/django_py3_1.11/lib/python3.6/site-packages/django/db/models/manager.py", line 85, in manager_method
    return getattr(self.get_queryset(), name)(*args, **kwargs)
  File "/Users/huangjianhao/.virtualenvs/django_py3_1.11/lib/python3.6/site-packages/django/db/models/query.py", line 392, in create
    obj = self.model(**kwargs)
  File "/Users/huangjianhao/.virtualenvs/django_py3_1.11/lib/python3.6/site-packages/django/contrib/auth/base_user.py", line 68, in __init__
    super(AbstractBaseUser, self).__init__(*args, **kwargs)
  File "/Users/huangjianhao/.virtualenvs/django_py3_1.11/lib/python3.6/site-packages/django/db/models/base.py", line 573, in __init__
    raise TypeError("'%s' is an invalid keyword argument for this function" % list(kwargs)[0])
TypeError: 'sms_code' is an invalid keyword argument for this function

ERROR 2018-10-28 11:13:49,897 basehttp 124 "POST /oauth/qq/user/ HTTP/1.1" 507 35
ERROR 2018-10-28 11:15:56,955 exceptions 26 [<oauth.views.QQAuthUserView object at 0x1116e7f28>] `create()` must be implemented.
ERROR 2018-10-28 11:15:56,956 basehttp 124 "POST /oauth/qq/user/ HTTP/1.1" 507 35
WARNING 2018-10-28 11:17:02,246 basehttp 124 "POST /oauth/qq/user/ HTTP/1.1" 400 49
INFO 2018-10-28 11:18:44,368 basehttp 124 "OPTIONS /oauth/qq/user/ HTTP/1.1" 200 0
WARNING 2018-10-28 11:18:44,391 basehttp 124 "POST /oauth/qq/user/ HTTP/1.1" 400 49
WARNING 2018-10-28 11:20:16,104 basehttp 124 "POST /oauth/qq/user/ HTTP/1.1" 400 49
WARNING 2018-10-28 11:20:31,998 basehttp 124 "POST /oauth/qq/user/ HTTP/1.1" 400 49
WARNING 2018-10-28 11:20:33,189 basehttp 124 "POST /oauth/qq/user/ HTTP/1.1" 400 49
WARNING 2018-10-28 11:20:53,648 basehttp 124 "POST /oauth/qq/user/ HTTP/1.1" 400 49
WARNING 2018-10-28 11:24:06,211 base 152 Not Found: /
WARNING 2018-10-28 11:24:06,212 basehttp 124 "GET / HTTP/1.1" 404 2916
INFO 2018-10-28 11:25:57,444 basehttp 124 "GET /oauth/qq/authorization/?next=/ HTTP/1.1" 200 195
ERROR 2018-10-28 11:26:13,718 qq_sdk 60 code=None msg=None
ERROR 2018-10-28 11:26:13,719 basehttp 124 "GET /oauth/qq/user/?code=91927A192FD555F97CBC827270C35244 HTTP/1.1" 503 28
INFO 2018-10-28 11:26:25,166 basehttp 124 "GET /oauth/qq/user/?code=4F8E9438DB02852FC0C30F7792E749F7 HTTP/1.1" 200 190
INFO 2018-10-28 11:26:30,237 basehttp 124 "GET /sms_code/13590299759/ HTTP/1.1" 200 16
ERROR 2018-10-28 11:27:04,680 exceptions 26 [<oauth.views.QQAuthUserView object at 0x11181acc0>] [Errno 60] Operation timed out
ERROR 2018-10-28 11:27:04,682 basehttp 124 "GET /oauth/qq/user/?code=91927A192FD555F97CBC827270C35244 HTTP/1.1" 507 35
INFO 2018-10-28 11:29:33,204 tasks 29 发送验证码短信[正常][ mobile: 13590299759 ]
INFO 2018-10-28 11:29:50,226 basehttp 124 "OPTIONS /oauth/qq/user/ HTTP/1.1" 200 0
WARNING 2018-10-28 11:29:50,255 basehttp 124 "POST /oauth/qq/user/ HTTP/1.1" 400 46
INFO 2018-10-28 14:07:25,449 basehttp 124 "GET /oauth/qq/authorization/?next=/ HTTP/1.1" 200 195
INFO 2018-10-28 14:07:40,075 basehttp 124 "GET /oauth/qq/user/?code=785D0AFCF0AAA6616C0A9A93297F4BDF HTTP/1.1" 200 190
INFO 2018-10-28 14:07:47,861 basehttp 124 "GET /sms_code/13590299759/ HTTP/1.1" 200 16
INFO 2018-10-28 14:07:48,343 tasks 29 发送验证码短信[正常][ mobile: 13590299759 ]
INFO 2018-10-28 14:08:11,836 basehttp 124 "OPTIONS /oauth/qq/user/ HTTP/1.1" 200 0
ERROR 2018-10-28 14:08:45,599 exceptions 26 [<oauth.views.QQAuthUserView object at 0x113052160>] 'password'
ERROR 2018-10-28 14:08:45,601 basehttp 124 "POST /oauth/qq/user/ HTTP/1.1" 507 35
ERROR 2018-10-28 14:09:50,360 exceptions 26 [<oauth.views.QQAuthUserView object at 0x113066470>] 'password'
ERROR 2018-10-28 14:09:50,367 basehttp 124 "POST /oauth/qq/user/ HTTP/1.1" 507 35
ERROR 2018-10-28 14:12:11,194 exceptions 26 [<oauth.views.QQAuthUserView object at 0x113050550>] 'password'
ERROR 2018-10-28 14:12:11,201 basehttp 124 "POST /oauth/qq/user/ HTTP/1.1" 507 35
INFO 2018-10-28 14:28:51,719 basehttp 124 "OPTIONS /oauth/qq/user/ HTTP/1.1" 200 0
WARNING 2018-10-28 14:33:08,725 basehttp 124 "POST /oauth/qq/user/ HTTP/1.1" 400 49
WARNING 2018-10-28 14:33:21,384 basehttp 124 "POST /oauth/qq/user/ HTTP/1.1" 400 49
INFO 2018-10-28 14:40:06,079 basehttp 124 "GET /oauth/qq/authorization/?next=/ HTTP/1.1" 200 195
INFO 2018-10-28 14:40:34,720 basehttp 124 "GET /oauth/qq/user/?code=12715453472A4623F2736FE65A3F91D9 HTTP/1.1" 200 190
INFO 2018-10-28 14:40:44,274 basehttp 124 "GET /sms_code/13590299759/ HTTP/1.1" 200 16
INFO 2018-10-28 14:40:44,278 tasks 29 发送验证码短信[正常][ mobile: 13590299759 ]
INFO 2018-10-28 14:40:57,597 basehttp 124 "OPTIONS /oauth/qq/user/ HTTP/1.1" 200 0
INFO 2018-10-28 14:40:57,710 basehttp 124 "POST /oauth/qq/user/ HTTP/1.1" 200 47
INFO 2018-10-28 15:57:09,595 basehttp 124 "OPTIONS /user/ HTTP/1.1" 200 0
WARNING 2018-10-28 15:57:09,661 basehttp 124 "GET /user/ HTTP/1.1" 401 38
WARNING 2018-10-28 15:57:33,823 basehttp 124 "GET /user/ HTTP/1.1" 401 38
WARNING 2018-10-28 15:57:35,749 basehttp 124 "GET /user/ HTTP/1.1" 401 38
INFO 2018-10-28 15:57:40,951 basehttp 124 "GET /oauth/qq/authorization/?next=/user_center_info.html HTTP/1.1" 200 216
INFO 2018-10-28 15:57:59,788 basehttp 124 "GET /oauth/qq/user/?code=C9EE45A02E9C6E50BA14FCCB734CDCAB HTTP/1.1" 200 47
INFO 2018-10-28 15:57:59,839 basehttp 124 "OPTIONS /user/ HTTP/1.1" 200 0
WARNING 2018-10-28 15:57:59,887 basehttp 124 "GET /user/ HTTP/1.1" 401 38
INFO 2018-10-28 16:07:53,138 basehttp 124 "GET /oauth/qq/authorization/?next=/user_center_info.html HTTP/1.1" 200 216
INFO 2018-10-28 16:08:26,532 basehttp 124 "GET /oauth/qq/user/?code=7B60EDFE847BFB60838DE0A52EAF8EC5 HTTP/1.1" 200 47
INFO 2018-10-28 16:08:26,578 basehttp 124 "OPTIONS /user/ HTTP/1.1" 200 0
WARNING 2018-10-28 16:08:26,584 basehttp 124 "GET /user/ HTTP/1.1" 401 38
INFO 2018-10-28 16:08:49,662 basehttp 124 "OPTIONS /authorizations/ HTTP/1.1" 200 0
INFO 2018-10-28 16:08:49,709 basehttp 124 "POST /authorizations/ HTTP/1.1" 200 209
INFO 2018-10-28 16:08:49,766 basehttp 124 "GET /user/ HTTP/1.1" 200 84
INFO 2018-10-28 16:08:49,771 basehttp 124 "OPTIONS /browse_histories/ HTTP/1.1" 200 0
WARNING 2018-10-28 16:08:49,778 base 152 Not Found: /browse_histories/
WARNING 2018-10-28 16:08:49,780 basehttp 124 "GET /browse_histories/ HTTP/1.1" 404 3146
WARNING 2018-10-28 16:09:04,065 base 152 Not Found: /browse_histories/
WARNING 2018-10-28 16:09:04,066 basehttp 124 "GET /browse_histories/ HTTP/1.1" 404 3146
WARNING 2018-10-28 16:09:07,270 basehttp 124 "GET /user/ HTTP/1.1" 401 38
WARNING 2018-10-28 16:09:08,998 basehttp 124 "GET /user/ HTTP/1.1" 401 38
WARNING 2018-10-28 16:09:16,481 basehttp 124 "GET /user/ HTTP/1.1" 401 38
WARNING 2018-10-28 16:09:18,301 basehttp 124 "GET /user/ HTTP/1.1" 401 38
WARNING 2018-10-28 16:09:49,903 basehttp 124 "GET /user/ HTTP/1.1" 401 38
WARNING 2018-10-28 16:14:25,589 basehttp 124 "GET /user/ HTTP/1.1" 401 38
INFO 2018-10-28 16:14:36,587 basehttp 124 "POST /authorizations/ HTTP/1.1" 200 209
INFO 2018-10-28 16:14:36,642 basehttp 124 "GET /user/ HTTP/1.1" 200 84
WARNING 2018-10-28 16:14:36,651 base 152 Not Found: /browse_histories/
WARNING 2018-10-28 16:14:36,651 basehttp 124 "GET /browse_histories/ HTTP/1.1" 404 3146
INFO 2018-10-28 16:14:49,741 basehttp 124 "GET /user/ HTTP/1.1" 200 84
WARNING 2018-10-28 16:14:49,749 base 152 Not Found: /browse_histories/
WARNING 2018-10-28 16:14:49,749 basehttp 124 "GET /browse_histories/ HTTP/1.1" 404 3146
INFO 2018-10-28 16:14:53,447 basehttp 124 "GET /user/ HTTP/1.1" 200 84
WARNING 2018-10-28 16:14:53,455 base 152 Not Found: /browse_histories/
WARNING 2018-10-28 16:14:53,456 basehttp 124 "GET /browse_histories/ HTTP/1.1" 404 3146
INFO 2018-10-29 16:32:32,901 basehttp 124 "OPTIONS /user/ HTTP/1.1" 200 0
WARNING 2018-10-29 16:32:32,929 basehttp 124 "GET /user/ HTTP/1.1" 401 35
INFO 2018-10-29 16:32:37,034 basehttp 124 "GET /oauth/qq/authorization/?next=/user_center_info.html HTTP/1.1" 200 216
INFO 2018-10-29 16:32:52,720 basehttp 124 "GET /oauth/qq/user/?code=0E9107BB89C6DB2E06652E26A616F915 HTTP/1.1" 200 47
INFO 2018-10-29 16:32:52,771 basehttp 124 "OPTIONS /user/ HTTP/1.1" 200 0
WARNING 2018-10-29 16:32:52,816 basehttp 124 "GET /user/ HTTP/1.1" 401 38
INFO 2018-10-29 16:33:05,041 basehttp 124 "OPTIONS /authorizations/ HTTP/1.1" 200 0
INFO 2018-10-29 16:33:05,094 basehttp 124 "POST /authorizations/ HTTP/1.1" 200 209
INFO 2018-10-29 16:33:05,145 basehttp 124 "GET /user/ HTTP/1.1" 200 84
INFO 2018-10-29 16:33:05,150 basehttp 124 "OPTIONS /browse_histories/ HTTP/1.1" 200 0
WARNING 2018-10-29 16:33:05,156 base 152 Not Found: /browse_histories/
WARNING 2018-10-29 16:33:05,157 basehttp 124 "GET /browse_histories/ HTTP/1.1" 404 3303
INFO 2018-10-29 16:33:53,800 basehttp 124 "OPTIONS /emails/ HTTP/1.1" 200 0
INFO 2018-10-29 16:33:53,893 basehttp 124 "PUT /emails/ HTTP/1.1" 200 39
INFO 2018-10-29 17:06:25,533 basehttp 124 "OPTIONS /user/ HTTP/1.1" 200 0
INFO 2018-10-29 17:06:25,572 basehttp 124 "GET /user/ HTTP/1.1" 200 84
INFO 2018-10-29 17:06:25,577 basehttp 124 "OPTIONS /browse_histories/ HTTP/1.1" 200 0
WARNING 2018-10-29 17:06:25,584 base 152 Not Found: /browse_histories/
WARNING 2018-10-29 17:06:25,584 basehttp 124 "GET /browse_histories/ HTTP/1.1" 404 3303
INFO 2018-10-29 17:06:51,398 basehttp 124 "OPTIONS /emails/ HTTP/1.1" 200 0
INFO 2018-10-29 17:06:51,518 basehttp 124 "PUT /emails/ HTTP/1.1" 200 39
WARNING 2018-10-29 17:07:05,380 base 152 Not Found: /emails/verification/
WARNING 2018-10-29 17:07:05,380 basehttp 124 "GET /emails/verification/?token=eyJhbGciOiJIUzI1NiIsImlhdCI6MTU0MDgwNDAxMSwiZXhwIjoxNTQwODkwNDExfQ.eyJ1c2VyX2lkIjoxLCJlbWFpbCI6ImVyaWNfamlhbmhhb0AxNjMuY29tIn0.Cy8jDN-QIqlUQYnOdS14kKeVqD6wWNjdd_5qE4MvIiI HTTP/1.1" 404 3489
INFO 2018-10-29 17:08:58,176 basehttp 124 "GET /user/ HTTP/1.1" 200 84
WARNING 2018-10-29 17:08:58,184 base 152 Not Found: /browse_histories/
WARNING 2018-10-29 17:08:58,184 basehttp 124 "GET /browse_histories/ HTTP/1.1" 404 3473
INFO 2018-10-29 17:09:08,197 basehttp 124 "PUT /emails/ HTTP/1.1" 200 39
WARNING 2018-10-29 17:09:16,110 basehttp 124 "GET /emails/verification/?token=eyJhbGciOiJIUzI1NiIsImlhdCI6MTU0MDgwNDE0OCwiZXhwIjoxNTQwODkwNTQ4fQ.eyJ1c2VyX2lkIjoxLCJlbWFpbCI6ImVyaWNfamlhbmhhb0AxNjMuY29tIn0.BcDeR-EbkD9wQ8yHYp3hkPrKUDDcEnb-cFeFvFUxnd4 HTTP/1.1" 401 43
INFO 2018-10-29 17:32:37,088 basehttp 124 "OPTIONS /user/ HTTP/1.1" 200 0
INFO 2018-10-29 17:32:37,118 basehttp 124 "GET /user/ HTTP/1.1" 200 84
INFO 2018-10-29 17:32:37,122 basehttp 124 "OPTIONS /browse_histories/ HTTP/1.1" 200 0
WARNING 2018-10-29 17:32:37,128 base 152 Not Found: /browse_histories/
WARNING 2018-10-29 17:32:37,129 basehttp 124 "GET /browse_histories/ HTTP/1.1" 404 3473
INFO 2018-10-29 17:32:47,595 basehttp 124 "OPTIONS /emails/ HTTP/1.1" 200 0
INFO 2018-10-29 17:32:47,725 basehttp 124 "PUT /emails/ HTTP/1.1" 200 39
WARNING 2018-10-29 17:32:55,329 basehttp 124 "GET /emails/verification/?token=eyJhbGciOiJIUzI1NiIsImlhdCI6MTU0MDgwNTU2NywiZXhwIjoxNTQwODkxOTY3fQ.eyJ1c2VyX2lkIjoxLCJlbWFpbCI6ImVyaWNfamlhbmhhb0AxNjMuY29tIn0.Zabxbs3jbJH4w-Y87sm6gVpk_KD5Y04U1iYDwf_vPEk HTTP/1.1" 401 43
INFO 2018-10-29 17:34:45,590 basehttp 124 "GET /user/ HTTP/1.1" 200 84
WARNING 2018-10-29 17:34:45,601 base 152 Not Found: /browse_histories/
WARNING 2018-10-29 17:34:45,602 basehttp 124 "GET /browse_histories/ HTTP/1.1" 404 3473
INFO 2018-10-29 17:35:00,611 basehttp 124 "PUT /emails/ HTTP/1.1" 200 39
WARNING 2018-10-29 17:35:21,061 basehttp 124 "GET /emails/verification/?token=eyJhbGciOiJIUzI1NiIsImlhdCI6MTU0MDgwNTcwMCwiZXhwIjoxNTQwODkyMTAwfQ.eyJ1c2VyX2lkIjoxLCJlbWFpbCI6ImVyaWNfamlhbmhhb0AxNjMuY29tIn0.SXnrfwY9nnDc6f7uf5apsW5tx-uK5GMt0O5f1_kqv1k HTTP/1.1" 401 43
INFO 2018-10-29 17:37:04,911 basehttp 124 "GET /user/ HTTP/1.1" 200 84
WARNING 2018-10-29 17:37:04,944 base 152 Not Found: /browse_histories/
WARNING 2018-10-29 17:37:04,951 basehttp 124 "GET /browse_histories/ HTTP/1.1" 404 3473
INFO 2018-10-29 17:37:20,506 basehttp 124 "PUT /emails/ HTTP/1.1" 200 39
INFO 2018-10-29 17:38:02,044 basehttp 124 "GET /emails/verification/?token=eyJhbGciOiJIUzI1NiIsImlhdCI6MTU0MDgwNTg0MCwiZXhwIjoxNTQwODkyMjQwfQ.eyJ1c2VyX2lkIjoxLCJlbWFpbCI6ImVyaWNfamlhbmhhb0AxNjMuY29tIn0.k7CYmifDhKAUQAg92uEveDRf_NEDMt-OxND1HfJwhCo HTTP/1.1" 200 96
INFO 2018-10-29 17:42:14,727 basehttp 124 "OPTIONS /user/ HTTP/1.1" 200 0
INFO 2018-10-29 17:42:14,761 basehttp 124 "GET /user/ HTTP/1.1" 200 84
INFO 2018-10-29 17:42:14,768 basehttp 124 "OPTIONS /browse_histories/ HTTP/1.1" 200 0
WARNING 2018-10-29 17:42:14,774 base 152 Not Found: /browse_histories/
WARNING 2018-10-29 17:42:14,774 basehttp 124 "GET /browse_histories/ HTTP/1.1" 404 3473
INFO 2018-10-29 17:42:26,451 basehttp 124 "OPTIONS /emails/ HTTP/1.1" 200 0
INFO 2018-10-29 17:42:26,524 basehttp 124 "PUT /emails/ HTTP/1.1" 200 39
INFO 2018-10-29 17:42:39,300 basehttp 124 "GET /emails/verification/?token=eyJhbGciOiJIUzI1NiIsImlhdCI6MTU0MDgwNjE0NiwiZXhwIjoxNTQwODkyNTQ2fQ.eyJ1c2VyX2lkIjoxLCJlbWFpbCI6ImVyaWNfamlhbmhhb0AxNjMuY29tIn0.0N0l2pMZRW3jA7hVsqsJhI6rli83eInGN2C39lXt4pw HTTP/1.1" 200 96
INFO 2018-10-29 17:43:29,686 basehttp 124 "GET /user/ HTTP/1.1" 200 84
WARNING 2018-10-29 17:43:29,762 base 152 Not Found: /browse_histories/
WARNING 2018-10-29 17:43:29,772 basehttp 124 "GET /browse_histories/ HTTP/1.1" 404 3473
INFO 2018-10-29 17:43:34,124 basehttp 124 "PUT /emails/ HTTP/1.1" 200 39
INFO 2018-10-29 17:44:23,163 basehttp 124 "GET /emails/verification/?token=eyJhbGciOiJIUzI1NiIsImlhdCI6MTU0MDgwNjIxMywiZXhwIjoxNTQwODkyNjEzfQ.eyJ1c2VyX2lkIjoxLCJlbWFpbCI6ImVyaWNfamlhbmhhb0AxNjMuY29tIn0.Bx8hJfHwp9m7GLHPmHbj5sx6iZ59EtFUStYVhcrk7UE HTTP/1.1" 200 96
INFO 2018-10-29 17:45:40,222 basehttp 124 "GET /user/ HTTP/1.1" 200 84
WARNING 2018-10-29 17:45:40,230 base 152 Not Found: /browse_histories/
WARNING 2018-10-29 17:45:40,232 basehttp 124 "GET /browse_histories/ HTTP/1.1" 404 3473
INFO 2018-10-29 17:45:42,470 basehttp 124 "PUT /emails/ HTTP/1.1" 200 39
INFO 2018-10-29 17:46:07,895 basehttp 124 "GET /emails/verification/?token=eyJhbGciOiJIUzI1NiIsImlhdCI6MTU0MDgwNjM0MiwiZXhwIjoxNTQwODkyNzQyfQ.eyJ1c2VyX2lkIjoxLCJlbWFpbCI6ImVyaWNfamlhbmhhb0AxNjMuY29tIn0.LeCNd672A5oFC3B-ddcj2dIhPw_XQkzvH6Hl75u8mrM HTTP/1.1" 200 96
INFO 2018-10-29 17:47:19,509 basehttp 124 "GET /user/ HTTP/1.1" 200 84
WARNING 2018-10-29 17:47:19,518 base 152 Not Found: /browse_histories/
WARNING 2018-10-29 17:47:19,519 basehttp 124 "GET /browse_histories/ HTTP/1.1" 404 3473
INFO 2018-10-29 17:47:22,279 basehttp 124 "PUT /emails/ HTTP/1.1" 200 39
INFO 2018-10-29 17:47:28,584 basehttp 124 "GET /emails/verification/?token=eyJhbGciOiJIUzI1NiIsImlhdCI6MTU0MDgwNjQ0MiwiZXhwIjoxNTQwODkyODQyfQ.eyJ1c2VyX2lkIjoxLCJlbWFpbCI6ImVyaWNfamlhbmhhb0AxNjMuY29tIn0.t2YfMvS7fb2NrSXimY1-ZxQOQE6hdYbVP7VjIsBpeDs HTTP/1.1" 200 96
INFO 2018-10-29 17:47:54,720 basehttp 124 "GET /user/ HTTP/1.1" 200 84
WARNING 2018-10-29 17:47:54,757 base 152 Not Found: /browse_histories/
WARNING 2018-10-29 17:47:54,765 basehttp 124 "GET /browse_histories/ HTTP/1.1" 404 3473
INFO 2018-10-29 17:47:58,354 basehttp 124 "PUT /emails/ HTTP/1.1" 200 39
INFO 2018-10-29 17:48:06,135 basehttp 124 "GET /emails/verification/?token=eyJhbGciOiJIUzI1NiIsImlhdCI6MTU0MDgwNjQ3OCwiZXhwIjoxNTQwODkyODc4fQ.eyJ1c2VyX2lkIjoxLCJlbWFpbCI6ImVyaWNfamlhbmhhb0AxNjMuY29tIn0.PthBHtB-c3SoilPlrEBo6RsC-R2d4yr6bFhH0FXZEyk HTTP/1.1" 200 96
INFO 2018-10-29 19:30:58,557 basehttp 124 "OPTIONS /user/ HTTP/1.1" 200 0
INFO 2018-10-29 19:30:58,597 basehttp 124 "GET /user/ HTTP/1.1" 200 84
INFO 2018-10-29 19:30:58,605 basehttp 124 "OPTIONS /browse_histories/ HTTP/1.1" 200 0
WARNING 2018-10-29 19:30:58,630 base 152 Not Found: /browse_histories/
WARNING 2018-10-29 19:30:58,632 basehttp 124 "GET /browse_histories/ HTTP/1.1" 404 3473
INFO 2018-10-29 19:31:05,351 basehttp 124 "OPTIONS /emails/ HTTP/1.1" 200 0
INFO 2018-10-29 19:31:05,489 basehttp 124 "PUT /emails/ HTTP/1.1" 200 39
INFO 2018-10-29 19:31:29,082 basehttp 124 "GET /emails/verification/?token=eyJhbGciOiJIUzI1NiIsImlhdCI6MTU0MDgxMjY2NSwiZXhwIjoxNTQwODk5MDY1fQ.eyJ1c2VyX2lkIjoxLCJlbWFpbCI6ImVyaWNfamlhbmhhb0AxNjMuY29tIn0.t5JBLx1zOvTLcSc9rZucDIfKbX6PzB9n0RlCxL9e--Q HTTP/1.1" 200 96
INFO 2018-10-29 19:35:00,956 basehttp 124 "GET /user/ HTTP/1.1" 200 84
WARNING 2018-10-29 19:35:00,989 base 152 Not Found: /browse_histories/
WARNING 2018-10-29 19:35:00,998 basehttp 124 "GET /browse_histories/ HTTP/1.1" 404 3473
INFO 2018-10-29 19:35:05,063 basehttp 124 "PUT /emails/ HTTP/1.1" 200 39
INFO 2018-10-29 19:50:18,049 basehttp 124 "OPTIONS /user/ HTTP/1.1" 200 0
INFO 2018-10-29 19:50:18,086 basehttp 124 "GET /user/ HTTP/1.1" 200 84
INFO 2018-10-29 19:50:18,091 basehttp 124 "OPTIONS /browse_histories/ HTTP/1.1" 200 0
WARNING 2018-10-29 19:50:18,097 base 152 Not Found: /browse_histories/
WARNING 2018-10-29 19:50:18,098 basehttp 124 "GET /browse_histories/ HTTP/1.1" 404 3473
INFO 2018-10-29 19:50:30,476 basehttp 124 "OPTIONS /emails/ HTTP/1.1" 200 0
INFO 2018-10-29 19:50:30,602 basehttp 124 "PUT /emails/ HTTP/1.1" 200 38
INFO 2018-10-29 19:51:06,513 basehttp 124 "GET /user/ HTTP/1.1" 200 84
WARNING 2018-10-29 19:51:06,522 base 152 Not Found: /browse_histories/
WARNING 2018-10-29 19:51:06,522 basehttp 124 "GET /browse_histories/ HTTP/1.1" 404 3473
INFO 2018-10-29 19:51:21,625 basehttp 124 "PUT /emails/ HTTP/1.1" 200 39
ERROR 2018-10-29 19:51:30,877 exceptions 26 [<users.views.VerifyEmailView object at 0x1119d6550>] 'str' object does not support item assignment
ERROR 2018-10-29 19:51:30,878 basehttp 124 "GET /emails/verification/?token=eyJhbGciOiJIUzI1NiIsImlhdCI6MTU0MDgxMzg4MSwiZXhwIjoxNTQwOTAwMjgxfQ.eyJ1c2VyX2lkIjoxLCJlbWFpbCI6ImVyaWNfamlhbmhhb0AxNjMuY29tIn0.okObob17eFnkumhTP1iE4Hc4hJC-Z4O8PJ3zTMczmAQ HTTP/1.1" 507 35
ERROR 2018-10-29 19:54:45,403 exceptions 26 [<users.views.VerifyEmailView object at 0x1112ea710>] 'str' object does not support item assignment
ERROR 2018-10-29 19:54:45,403 basehttp 124 "GET /emails/verification/?token=eyJhbGciOiJIUzI1NiIsImlhdCI6MTU0MDgxMzg4MSwiZXhwIjoxNTQwOTAwMjgxfQ.eyJ1c2VyX2lkIjoxLCJlbWFpbCI6ImVyaWNfamlhbmhhb0AxNjMuY29tIn0.okObob17eFnkumhTP1iE4Hc4hJC-Z4O8PJ3zTMczmAQ HTTP/1.1" 507 35
ERROR 2018-10-29 19:57:57,484 exceptions 26 [<users.views.VerifyEmailView object at 0x111da8fd0>] 'str' object does not support item assignment
ERROR 2018-10-29 19:57:57,488 basehttp 124 "GET /emails/verification/?token=eyJhbGciOiJIUzI1NiIsImlhdCI6MTU0MDgxMzg4MSwiZXhwIjoxNTQwOTAwMjgxfQ.eyJ1c2VyX2lkIjoxLCJlbWFpbCI6ImVyaWNfamlhbmhhb0AxNjMuY29tIn0.okObob17eFnkumhTP1iE4Hc4hJC-Z4O8PJ3zTMczmAQ HTTP/1.1" 507 35
ERROR 2018-10-29 19:59:13,378 exceptions 26 [<users.views.VerifyEmailView object at 0x111dd0390>] 'str' object does not support item assignment
ERROR 2018-10-29 19:59:13,381 basehttp 124 "GET /emails/verification/?token=eyJhbGciOiJIUzI1NiIsImlhdCI6MTU0MDgxMzg4MSwiZXhwIjoxNTQwOTAwMjgxfQ.eyJ1c2VyX2lkIjoxLCJlbWFpbCI6ImVyaWNfamlhbmhhb0AxNjMuY29tIn0.okObob17eFnkumhTP1iE4Hc4hJC-Z4O8PJ3zTMczmAQ HTTP/1.1" 507 35
ERROR 2018-10-29 20:00:03,424 exceptions 26 [<users.views.VerifyEmailView object at 0x111663320>] 'str' object does not support item assignment
ERROR 2018-10-29 20:00:03,428 basehttp 124 "GET /emails/verification/?token=eyJhbGciOiJIUzI1NiIsImlhdCI6MTU0MDgxMzg4MSwiZXhwIjoxNTQwOTAwMjgxfQ.eyJ1c2VyX2lkIjoxLCJlbWFpbCI6ImVyaWNfamlhbmhhb0AxNjMuY29tIn0.okObob17eFnkumhTP1iE4Hc4hJC-Z4O8PJ3zTMczmAQ HTTP/1.1" 507 35
INFO 2018-10-29 20:10:45,186 basehttp 124 "OPTIONS /user/ HTTP/1.1" 200 0
INFO 2018-10-29 20:10:45,327 basehttp 124 "GET /user/ HTTP/1.1" 200 84
INFO 2018-10-29 20:10:45,342 basehttp 124 "OPTIONS /browse_histories/ HTTP/1.1" 200 0
WARNING 2018-10-29 20:10:45,373 base 152 Not Found: /browse_histories/
WARNING 2018-10-29 20:10:45,381 basehttp 124 "GET /browse_histories/ HTTP/1.1" 404 3473
INFO 2018-10-29 20:10:58,899 basehttp 124 "OPTIONS /emails/ HTTP/1.1" 200 0
INFO 2018-10-29 20:10:59,096 basehttp 124 "PUT /emails/ HTTP/1.1" 200 39
INFO 2018-10-29 20:11:59,798 basehttp 124 "GET /user/ HTTP/1.1" 200 84
WARNING 2018-10-29 20:11:59,855 base 152 Not Found: /browse_histories/
WARNING 2018-10-29 20:11:59,858 basehttp 124 "GET /browse_histories/ HTTP/1.1" 404 3473
INFO 2018-10-29 20:12:11,535 basehttp 124 "PUT /emails/ HTTP/1.1" 200 39
INFO 2018-10-29 20:12:57,653 basehttp 124 "GET /emails/verification/?token=eyJhbGciOiJIUzI1NiIsImlhdCI6MTU0MDgxNTEzMSwiZXhwIjoxNTQwOTAxNTMxfQ.eyJ1c2VyX2lkIjoxLCJlbWFpbCI6ImVyaWNfamlhbmhhb0AxNjMuY29tIn0.fWokFsbsSUqq0ecoM_l7HMYa5NkvkI7bq1vNEhG8TyU HTTP/1.1" 200 16
INFO 2018-10-29 20:12:57,702 basehttp 124 "GET /emails/verification/?token=eyJhbGciOiJIUzI1NiIsImlhdCI6MTU0MDgxNTA1OCwiZXhwIjoxNTQwOTAxNDU4fQ.eyJ1c2VyX2lkIjoxLCJlbWFpbCI6ImVyaWNfamlhbmhhb0AxNjMuY29tIn0.fROgmnzmC5kGuSn46HjtSKTlggxQE__1Q1mUYu4HnlY HTTP/1.1" 200 16
INFO 2018-10-29 21:42:24,559 basehttp 124 "GET /oauth/qq/authorization/?next=/ HTTP/1.1" 200 195
INFO 2018-10-29 21:42:40,056 basehttp 124 "GET /oauth/qq/user/?code=4C29D03197B93106053C875EA800B7A9 HTTP/1.1" 200 47
INFO 2018-10-31 16:52:42,425 basehttp 124 "OPTIONS /user/ HTTP/1.1" 200 0
WARNING 2018-10-31 16:52:42,481 basehttp 124 "GET /user/ HTTP/1.1" 401 38
INFO 2018-10-31 16:52:54,641 basehttp 124 "OPTIONS /authorizations/ HTTP/1.1" 200 0
INFO 2018-10-31 16:52:54,695 basehttp 124 "POST /authorizations/ HTTP/1.1" 200 236
INFO 2018-10-31 16:52:54,766 basehttp 124 "GET /user/ HTTP/1.1" 200 103
INFO 2018-10-31 16:52:54,773 basehttp 124 "OPTIONS /browse_histories/ HTTP/1.1" 200 0
WARNING 2018-10-31 16:52:54,782 base 152 Not Found: /browse_histories/
WARNING 2018-10-31 16:52:54,783 basehttp 124 "GET /browse_histories/ HTTP/1.1" 404 4644
WARNING 2018-10-31 16:54:14,774 base 152 Not Found: /browse_histories/
WARNING 2018-10-31 16:54:14,775 basehttp 124 "GET /browse_histories/ HTTP/1.1" 404 4644
INFO 2018-10-31 16:55:30,776 basehttp 124 "OPTIONS /addresses/ HTTP/1.1" 200 0
WARNING 2018-10-31 16:55:30,790 base 152 Not Found: /addresses/
WARNING 2018-10-31 16:55:30,794 basehttp 124 "GET /addresses/ HTTP/1.1" 404 4623
INFO 2018-10-31 16:55:30,794 basehttp 124 "GET /areas/ HTTP/1.1" 200 1204
WARNING 2018-10-31 16:55:33,303 base 152 Not Found: /addresses/
INFO 2018-10-31 16:55:33,303 basehttp 124 "GET /areas/ HTTP/1.1" 200 1204
WARNING 2018-10-31 16:55:33,304 basehttp 124 "GET /addresses/ HTTP/1.1" 404 4623
ERROR 2018-10-31 16:55:41,111 exceptions 26 [<areas.views.AreasViewSet object at 0x1117f8dd8>] The field 'subs' was declared on serializer SubAreaSerializer, but has not been included in the 'fields' option.
ERROR 2018-10-31 16:55:41,112 basehttp 124 "GET /areas/110000/ HTTP/1.1" 507 35
ERROR 2018-10-31 19:31:08,076 exceptions 26 [<areas.views.AreasViewSet object at 0x1113f67f0>] The field 'subs' was declared on serializer SubAreaSerializer, but has not been included in the 'fields' option.
ERROR 2018-10-31 19:31:08,077 basehttp 124 "GET /areas/110000/ HTTP/1.1" 507 35
INFO 2018-10-31 19:31:27,961 basehttp 124 "OPTIONS /addresses/ HTTP/1.1" 200 0
WARNING 2018-10-31 19:31:27,972 base 152 Not Found: /addresses/
WARNING 2018-10-31 19:31:27,973 basehttp 124 "GET /addresses/ HTTP/1.1" 404 4623
INFO 2018-10-31 19:31:27,984 basehttp 124 "GET /areas/ HTTP/1.1" 200 1204
ERROR 2018-10-31 19:31:38,617 exceptions 26 [<areas.views.AreasViewSet object at 0x110f9bd68>] The field 'subs' was declared on serializer SubAreaSerializer, but has not been included in the 'fields' option.
ERROR 2018-10-31 19:31:38,618 basehttp 124 "GET /areas/110000/ HTTP/1.1" 507 35
ERROR 2018-10-31 19:50:21,765 exceptions 26 [<areas.views.AreasViewSet object at 0x110fc2e10>] The field 'subs' was declared on serializer SubAreaSerializer, but has not been included in the 'fields' option.
ERROR 2018-10-31 19:50:21,766 basehttp 124 "GET /areas/130000/ HTTP/1.1" 507 35
ERROR 2018-10-31 19:50:51,478 exceptions 26 [<areas.views.AreasViewSet object at 0x110fcf9e8>] The field 'subs' was declared on serializer SubAreaSerializer, but has not been included in the 'fields' option.
ERROR 2018-10-31 19:50:51,479 basehttp 124 "GET /areas/110000/ HTTP/1.1" 507 35
INFO 2018-10-31 19:59:27,498 basehttp 124 "GET /areas/220000/ HTTP/1.1" 200 353
INFO 2018-10-31 19:59:34,901 basehttp 124 "GET /areas/220400/ HTTP/1.1" 200 173
INFO 2018-11-01 15:19:43,918 basehttp 124 "GET /areas/440000/ HTTP/1.1" 200 734
INFO 2018-11-01 15:19:47,974 basehttp 124 "GET /areas/440300/ HTTP/1.1" 200 239
INFO 2018-11-01 15:19:59,299 basehttp 124 "OPTIONS /addresses/ HTTP/1.1" 200 0
WARNING 2018-11-01 15:19:59,306 base 152 Not Found: /addresses/
WARNING 2018-11-01 15:19:59,306 basehttp 124 "POST /addresses/ HTTP/1.1" 404 4624
WARNING 2018-11-01 15:20:03,262 base 152 Not Found: /addresses/
WARNING 2018-11-01 15:20:03,263 basehttp 124 "POST /addresses/ HTTP/1.1" 404 4624
ERROR 2018-11-01 15:23:49,140 exceptions 26 [<users.views.AddressViewSet object at 0x11097d828>] (1048, "Column 'user_id' cannot be null")
ERROR 2018-11-01 15:23:49,141 basehttp 124 "POST /addresses/ HTTP/1.1" 507 35
INFO 2018-11-01 15:26:08,744 basehttp 124 "GET /areas/440000/ HTTP/1.1" 200 734
INFO 2018-11-01 15:26:11,604 basehttp 124 "GET /areas/440300/ HTTP/1.1" 200 239
ERROR 2018-11-01 15:26:35,691 exceptions 26 [<users.views.AddressViewSet object at 0x1117ccf60>] (1048, "Column 'user_id' cannot be null")
ERROR 2018-11-01 15:26:35,691 basehttp 124 "POST /addresses/ HTTP/1.1" 507 35
ERROR 2018-11-01 15:28:30,618 exceptions 26 [<users.views.AddressViewSet object at 0x1117ccdd8>] (1048, "Column 'user_id' cannot be null")
ERROR 2018-11-01 15:28:30,618 basehttp 124 "POST /addresses/ HTTP/1.1" 507 35
INFO 2018-11-01 15:32:27,275 basehttp 124 "OPTIONS /addresses/ HTTP/1.1" 200 0
INFO 2018-11-01 15:32:27,388 basehttp 124 "POST /addresses/ HTTP/1.1" 201 246
INFO 2018-11-01 15:32:33,648 basehttp 124 "GET /areas/ HTTP/1.1" 200 1204
ERROR 2018-11-01 15:32:33,649 exceptions 26 [<users.views.AddressViewSet object at 0x1118f4c88>] Cannot resolve keyword 'is_delete' into field. Choices are: city, city_id, create_time, district, district_id, email, id, is_deleted, mobile, place, province, province_id, receiver, tel, title, update_time, user, user_id, users
ERROR 2018-11-01 15:32:33,649 basehttp 124 "GET /addresses/ HTTP/1.1" 507 35
INFO 2018-11-01 15:34:52,766 basehttp 124 "GET /areas/ HTTP/1.1" 200 1204
ERROR 2018-11-01 15:34:52,773 exceptions 26 [<users.views.AddressViewSet object at 0x111920f98>] Cannot resolve keyword 'is_delete' into field. Choices are: city, city_id, create_time, district, district_id, email, id, is_deleted, mobile, place, province, province_id, receiver, tel, title, update_time, user, user_id, users
ERROR 2018-11-01 15:34:52,774 basehttp 124 "GET /addresses/ HTTP/1.1" 507 35
INFO 2018-11-01 15:36:14,256 basehttp 124 "GET /areas/ HTTP/1.1" 200 1204
INFO 2018-11-01 15:36:14,265 basehttp 124 "GET /addresses/ HTTP/1.1" 200 310
INFO 2018-11-01 15:36:30,337 basehttp 124 "GET /areas/440000/ HTTP/1.1" 200 734
INFO 2018-11-01 15:36:30,338 basehttp 124 "GET /areas/440300/ HTTP/1.1" 200 239
INFO 2018-11-01 15:36:34,397 basehttp 124 "OPTIONS /addresses/1/ HTTP/1.1" 200 0
INFO 2018-11-01 15:36:34,517 basehttp 124 "PUT /addresses/1/ HTTP/1.1" 200 252
INFO 2018-11-01 15:36:46,337 basehttp 124 "PUT /addresses/1/ HTTP/1.1" 200 268
INFO 2018-11-01 15:36:50,553 basehttp 124 "GET /areas/ HTTP/1.1" 200 1204
INFO 2018-11-01 15:36:50,568 basehttp 124 "GET /addresses/ HTTP/1.1" 200 332
INFO 2018-11-01 15:37:01,815 basehttp 124 "OPTIONS /addresses/1/status/ HTTP/1.1" 200 0
INFO 2018-11-01 15:37:01,864 basehttp 124 "PUT /addresses/1/status/ HTTP/1.1" 200 16
INFO 2018-11-01 15:37:03,994 basehttp 124 "GET /areas/ HTTP/1.1" 200 1204
INFO 2018-11-01 15:37:04,008 basehttp 124 "GET /addresses/ HTTP/1.1" 200 329
INFO 2018-11-01 15:37:23,779 basehttp 124 "GET /areas/110000/ HTTP/1.1" 200 74
INFO 2018-11-01 15:37:26,912 basehttp 124 "GET /areas/450000/ HTTP/1.1" 200 518
INFO 2018-11-01 15:37:29,135 basehttp 124 "GET /areas/440000/ HTTP/1.1" 200 734
INFO 2018-11-01 15:37:31,805 basehttp 124 "GET /areas/441700/ HTTP/1.1" 200 173
INFO 2018-11-01 15:37:38,414 basehttp 124 "GET /areas/440300/ HTTP/1.1" 200 239
INFO 2018-11-01 15:37:49,195 basehttp 124 "POST /addresses/ HTTP/1.1" 201 246
INFO 2018-11-01 15:37:51,184 basehttp 124 "GET /areas/ HTTP/1.1" 200 1204
INFO 2018-11-01 15:37:51,202 basehttp 124 "GET /addresses/ HTTP/1.1" 200 576
INFO 2018-11-01 15:37:55,876 basehttp 124 "OPTIONS /addresses/2/ HTTP/1.1" 200 0
INFO 2018-11-01 15:37:55,949 basehttp 124 "DELETE /addresses/2/ HTTP/1.1" 204 0
INFO 2018-11-01 15:41:19,606 basehttp 124 "GET /areas/ HTTP/1.1" 200 1204
INFO 2018-11-01 15:41:19,609 basehttp 124 "GET /addresses/ HTTP/1.1" 200 329
INFO 2018-11-01 15:41:28,553 basehttp 124 "GET /areas/ HTTP/1.1" 200 1204
INFO 2018-11-01 15:41:28,567 basehttp 124 "GET /addresses/ HTTP/1.1" 200 329
